Workbook

Sheet Данные
A1: ФИО менеджера | B1: ФИО клиента | C1: Дата сделки | D1: Сумма сделки | E1: NPS
A2: Ткаченко Андрей Олегович | B2: Лебедева Виктория Дмитриевна | C2: 2023-09-01 | D2: 31810 | E2: 5
A3: Яковлев Артем Игоревич | B3: Семенов Дмитрий Олегович | C3: 2023-09-01 | D3: 79983 | E3: 8
A4: Кузнецов Дмитрий Львович | B4: Новикова Екатерина Ивановна | C4: 2023-09-01 | D4: 65103 | E4: 7
A5: Семенова Ирина Валерьевна | B5: Егорова Юлия Алексеевна | C5: 2023-09-01 | D5: 45916 | E5: 8
A6: Громова Мария Ильинична | B6: Петров Илья Михайлович | C6: 2023-09-04 | D6: 26479 | E6: 7
A7: Яковлев Артем Игоревич | B7: Кузнецова Полина Романовна | C7: 2023-09-04 | D7: 65924 | E7: 8
A8: Сидорова Елена Васильевна | B8: Лебедева Полина Ивановна | C8: 2023-09-04 | D8: 84442 | E8: 5
A9: Яковлев Артем Игоревич | B9: Кузнецов Никита Андреевич | C9: 2023-09-04 | D9: 36848 | E9: 6
A10: Белов Алексей Константинович | B10: Кузнецова Мария Юрьевна | C10: 2023-09-04 | D10: 27991 | E10: 7
A11: Громова Мария Ильинична | B11: Петрова Вероника Александровна | C11: 2023-09-04 | D11: 21080 | E11: 9
A12: Яковлев Артем Игоревич | B12: Васильев Матвей Романович | C12: 2023-09-04 | D12: 13650 | E12: 4
A13: Сидорова Елена Васильевна | B13: Егоров Артем Никитич | C13: 2023-09-05 | D13: 36816 | E13: 2
... A1001: Ткаченко Андрей Олегович | B1001: Васильева Александра Александровна | C1001: 2024-09-02 | D1001: 49150 | E1001: 8

Sheet результат
A1: ФИО студента: | B1: Шемякина Варвара Алексеевна
A2: Задача 1 | B2: Для каждого менеджера найти метрики: | G2: ФИО Менеджера (по алфавиту) | H2: Клиенты | I2: Сумма | J2: Длительность, дни | K2: NPS
B3: - количество клиентов - (столбец H) | F3: 1 | G3: Белов Алексей Константинович | H3: =COUNTIF('Задача 1'!B:B,результат!G3) -> 75 | I3: =SUMIF(Данные!A:A,результат!G3,Данные!D:D) -> 5014390 | J3: =VLOOKUP(G3,'Задача 1.2'!A:C,3,0) -> 333 | K3: =( COUNTIFS(Данные!A:A,результат!G3,Данные!E:E,">=9") - COUNTIFS(Данные!A:A,результат!G3,Данные!E:E,"<=6") ) / COUNTIFS(Данные!A:A,результат!G3,Данные!E:E,"<=0") -> -16
B4: - сумма проектов - (столбец I) | F4: 2 | G4: Громова Мария Ильинична | H4: =COUNTIF('Задача 1'!B:B,результат!G4) -> 77 | I4: =SUMIF(Данные!A:A,результат!G4,Данные!D:D) -> 5117834 | J4: =VLOOKUP(G4,'Задача 1.2'!A:C,3,0) -> 227 | K4: =( COUNTIFS(Данные!A:A,результат!G4,Данные!E:E,">=9") - COUNTIFS(Данные!A:A,результат!G4,Данные!E:E,"<=6") ) / COUNTIFS(Данные!A:A,результат!G4,Данные!E:E,"<=0") -> -14
B5: - длительность работы с клиентом от первой сделки до последней - (столбец J) | F5: 3 | G5: Иванова Анна Сергеевна | H5: =COUNTIF('Задача 1'!B:B,результат!G5) -> 63 | I5: =SUMIF(Данные!A:A,результат!G5,Данные!D:D) -> 3924069 | J5: =VLOOKUP(G5,'Задача 1.2'!A:C,3,0) -> 221 | K5: =( COUNTIFS(Данные!A:A,результат!G5,Данные!E:E,">=9") - COUNTIFS(Данные!A:A,результат!G5,Данные!E:E,"<=6") ) / COUNTIFS(Данные!A:A,результат!G5,Данные!E:E,"<=0") -> -9
B6: (для каждого менеджера определить самого долгого клиента в днях | F6: 4 | G6: Кузнецов Дмитрий Львович | H6: =COUNTIF('Задача 1'!B:B,результат!G6) -> 67 | I6: =SUMIF(Данные!A:A,результат!G6,Данные!D:D) -> 4748937 | J6: =VLOOKUP(G6,'Задача 1.2'!A:C,3,0) -> 262 | K6: =( COUNTIFS(Данные!A:A,результат!G6,Данные!E:E,">=9") - COUNTIFS(Данные!A:A,результат!G6,Данные!E:E,"<=6") ) / COUNTIFS(Данные!A:A,результат!G6,Данные!E:E,"<=0") -> -29
B7: от даты заключения первого проекта до даты заключения последнего проекта). | F7: 5 | G7: Новикова Ольга Петровна | H7: =COUNTIF('Задача 1'!B:B,результат!G7) -> 75 | I7: =SUMIF(Данные!A:A,результат!G7,Данные!D:D) -> 4941526 | J7: =VLOOKUP(G7,'Задача 1.2'!A:C,3,0) -> 323 | K7: =( COUNTIFS(Данные!A:A,результат!G7,Данные!E:E,">=9") - COUNTIFS(Данные!A:A,результат!G7,Данные!E:E,"<=6") ) / COUNTIFS(Данные!A:A,результат!G7,Данные!E:E,"<=0") -> -19
B8: - NPS по всем проектам - (столбец K) | F8: 6 | G8: Орлов Павел Денисович | H8: =COUNTIF('Задача 1'!B:B,результат!G8) -> 69 | I8: =SUMIF(Данные!A:A,результат!G8,Данные!D:D) -> 4515870 | J8: =VLOOKUP(G8,'Задача 1.2'!A:C,3,0) -> 300 | K8: =( COUNTIFS(Данные!A:A,результат!G8,Данные!E:E,">=9") - COUNTIFS(Данные!A:A,результат!G8,Данные!E:E,"<=6") ) / COUNTIFS(Данные!A:A,результат!G8,Данные!E:E,"<=0") -> -14
F9: 7 | G9: Петров Владимир Кириллович | H9: =COUNTIF('Задача 1'!B:B,результат!G9) -> 72 | I9: =SUMIF(Данные!A:A,результат!G9,Данные!D:D) -> 5071015 | J9: =VLOOKUP(G9,'Задача 1.2'!A:C,3,0) -> 286 | K9: =( COUNTIFS(Данные!A:A,результат!G9,Данные!E:E,">=9") - COUNTIFS(Данные!A:A,результат!G9,Данные!E:E,"<=6") ) / COUNTIFS(Данные!A:A,результат!G9,Данные!E:E,"<=0") -> -15.5
F10: 8 | G10: Семенова Ирина Валерьевна | H10: =COUNTIF('Задача 1'!B:B,результат!G10) -> 50 | I10: =SUMIF(Данные!A:A,результат!G10,Данные!D:D) -> 3860169 | J10: =VLOOKUP(G10,'Задача 1.2'!A:C,3,0) -> 268 | K10: =( COUNTIFS(Данные!A:A,результат!G10,Данные!E:E,">=9") - COUNTIFS(Данные!A:A,результат!G10,Данные!E:E,"<=6") ) / COUNTIFS(Данные!A:A,результат!G10,Данные!E:E,"<=0") -> -12
F11: 9 | G11: Сидорова Елена Васильевна | H11: =COUNTIF('Задача 1'!B:B,результат!G11) -> 59 | I11: =SUMIF(Данные!A:A,результат!G11,Данные!D:D) -> 4408761 | J11: =VLOOKUP(G11,'Задача 1.2'!A:C,3,0) -> 302 | K11: =( COUNTIFS(Данные!A:A,результат!G11,Данные!E:E,">=9") - COUNTIFS(Данные!A:A,результат!G11,Данные!E:E,"<=6") ) / COUNTIFS(Данные!A:A,результат!G11,Данные!E:E,"<=0") -> -27
B12: Определить самого эффективного менеджера: | F12: 10 | G12: Ткаченко Андрей Олегович | H12: =COUNTIF('Задача 1'!B:B,результат!G12) -> 64 | I12: =SUMIF(Данные!A:A,результат!G12,Данные!D:D) -> 4502588 | J12: =VLOOKUP(G12,'Задача 1.2'!A:C,3,0) -> 280 | K12: =( COUNTIFS(Данные!A:A,результат!G12,Данные!E:E,">=9") - COUNTIFS(Данные!A:A,результат!G12,Данные!E:E,"<=6") ) / COUNTIFS(Данные!A:A,результат!G12,Данные!E:E,"<=0") -> -19
A13: по количеству клиентов | B13: =INDEX(G3:G14,MATCH(MAX(H3:H14),H3:H14,0)) -> Громова Мария Ильинична | F13: 11 | G13: Фролов Сергей Викторович | H13: =COUNTIF('Задача 1'!B:B,результат!G13) -> 67 | I13: =SUMIF(Данные!A:A,результат!G13,Данные!D:D) -> 4297231 | J13: =VLOOKUP(G13,'Задача 1.2'!A:C,3,0) -> 231 | K13: =( COUNTIFS(Данные!A:A,результат!G13,Данные!E:E,">=9") - COUNTIFS(Данные!A:A,результат!G13,Данные!E:E,"<=6") ) / COUNTIFS(Данные!A:A,результат!G13,Данные!E:E,"<=0") -> -10.5
F14: 12 | G14: Яковлев Артем Игоревич | H14: =COUNTIF('Задача 1'!B:B,результат!G14) -> 76 | I14: =SUMIF(Данные!A:A,результат!G14,Данные!D:D) -> 5294051 | J14: =VLOOKUP(G14,'Задача 1.2'!A:C,3,0) -> 329 | K14: =( COUNTIFS(Данные!A:A,результат!G14,Данные!E:E,">=9") - COUNTIFS(Данные!A:A,результат!G14,Данные!E:E,"<=6") ) / COUNTIFS(Данные!A:A,результат!G14,Данные!E:E,"<=0") -> -21.5
A15: по сумме проектов | B15: =INDEX(G3:G14,MATCH(MAX(I3:I14),I3:I14,0)) -> Яковлев Артем Игоревич
A17: по длительности работы | B17: =INDEX(G3:G14,MATCH(MAX(J3:J14),J3:J14,0)) -> Белов Алексей Константинович
A19: NPS | B19: =INDEX(G3:G14,MATCH(MAX(K3:K14),K3:K14,0)) -> Иванова Анна Сергеевна
A23: Задача 2 | B23: Оценить клиентов | G23: ТОП 10 клиентов по продажам
B24: - доходности (вывести топ 10 клиентов) | G24: ФИО | H24: Проекты | I24: Сумма
B25: - не переходил к другим менеджерам - вывести первых 10 по алфавиту | F25: 1 | G25: Кузнецов Михаил Артемович | H25: 2 | I25: 883676
B26: - по длительности (сколько месяцев суммарно обслуживался клиент) | F26: 2 | G26: Лебедева Анна Викторовна | H26: 5 | I26: 746080
F27: 3 | G27: Орлов Александр Иванович | H27: 3 | I27: 680657
F28: 4 | G28: Морозова Мария Дмитриевна | H28: 3 | I28: 636973
F29: 5 | G29: Степанова Полина Артемовна | H29: 8 | I29: 610926
F30: 6 | G30: Морозова София Геннадьевна | H30: 5 | I30: 596460
F31: 7 | G31: Егорова Алиса Егоровна | H31: 3 | I31: 583616
F32: 8 | G32: Кузнецов Иван Ильич | H32: 3 | I32: 565367
F33: 9 | G33: Петров Алексей Олегович | H33: 7 | I33: 561141
F34: 10 | G34: Морозова Валерия Ильинична | H34: 4 | I34: 561096
G37: 10 клиентов, которые обслуживались у одного менеджера (в алфавитном порядке)
G38: ФИО | H38: Проекты | I38: Сумма
F39: 1 | G39: Алексеева Ольга Сергеевна | H39: 3 | I39: 446016
F40: 2 | G40: Козлова Екатерина Олеговна | H40: 5 | I40: 163989
F41: 3 | G41: Кузнецова Юлия Андреевна | H41: 1 | I41: 0
F42: 4 | G42: Лебедев Константин Алексеевич | H42: 3 | I42: 326968
F43: 5 | G43: Морозов Кирилл Геннадьевич | H43: 6 | I43: 97355
F44: 6 | G44: Морозова Ольга Дмитриевна | H44: 5 | I44: 101763
F45: 7 | G45: Сидорова Наталья Викторовна | H45: 2 | I45: 387713
F46: 8 | G46: Смирнова Алиса Кирилловна | H46: 11 | I46: 132173
F47: 9 | G47: Смирнова Дарья Александровна | H47: 7 | I47: 278272
...

Sheet Лист2

Sheet Задача 1
A1: ФИО менеджера | B1: ФИО менеджера | C1: ФИО клиента | D1: Дата 1 | E1: Дата 2 | F1: Кол-во | K1: ФИО менеджера | L1: ФИО клиента | M1: Дата сделки | O1: ФИО менеджера | P1: ФИО клиента | Q1: Дата сделки
A2: Белов Алексей Константинович | B2: Белов Алексей Константинович | C2: Алексеев Матвей Александрович | D2: =VLOOKUP(B2&C2,J:M,4,0) -> 2024-02-12 | E2: =VLOOKUP(B2&C2,N:Q,4,0) -> 2024-02-12 | F2: =E2-D2 -> 0 | J2: =K2&L2 -> Ткаченко Андрей ОлеговичЛебедева Виктория Дмитриевна | K2: Ткаченко Андрей Олегович | L2: Лебедева Виктория Дмитриевна | M2: 2023-09-01 | N2: =O2&P2 -> Иванова Анна СергеевнаНовикова Екатерина Михайловна | O2: Иванова Анна Сергеевна | P2: Новикова Екатерина Михайловна | Q2: 2024-09-02
A3: Громова Мария Ильинична | B3: Белов Алексей Константинович | C3: Алексеева Елена Кирилловна | D3: =VLOOKUP(B3&C3,J:M,4,0) -> 2023-11-03 | E3: =VLOOKUP(B3&C3,N:Q,4,0) -> 2024-06-05 | F3: =E3-D3 -> 215 | J3: =K3&L3 -> Яковлев Артем ИгоревичСеменов Дмитрий Олегович | K3: Яковлев Артем Игоревич | L3: Семенов Дмитрий Олегович | M3: 2023-09-01 | N3: =O3&P3 -> Семенова Ирина ВалерьевнаЛебедев Максим Михайлович | O3: Семенова Ирина Валерьевна | P3: Лебедев Максим Михайлович | Q3: 2024-09-02
A4: Иванова Анна Сергеевна | B4: Белов Алексей Константинович | C4: Алексеева Светлана Станиславовна | D4: =VLOOKUP(B4&C4,J:M,4,0) -> 2023-09-14 | E4: =VLOOKUP(B4&C4,N:Q,4,0) -> 2023-09-14 | F4: =E4-D4 -> 0 | J4: =K4&L4 -> Кузнецов Дмитрий ЛьвовичНовикова Екатерина Ивановна | K4: Кузнецов Дмитрий Львович | L4: Новикова Екатерина Ивановна | M4: 2023-09-01 | N4: =O4&P4 -> Ткаченко Андрей ОлеговичВасильева Александра Александровна | O4: Ткаченко Андрей Олегович | P4: Васильева Александра Александровна | Q4: 2024-09-02
A5: Кузнецов Дмитрий Львович | B5: Белов Алексей Константинович | C5: Васильев Матвей Геннадьевич | D5: =VLOOKUP(B5&C5,J:M,4,0) -> 2023-12-27 | E5: =VLOOKUP(B5&C5,N:Q,4,0) -> 2023-12-27 | F5: =E5-D5 -> 0 | J5: =K5&L5 -> Семенова Ирина ВалерьевнаЕгорова Юлия Алексеевна | K5: Семенова Ирина Валерьевна | L5: Егорова Юлия Алексеевна | M5: 2023-09-01 | N5: =O5&P5 -> Фролов Сергей ВикторовичПетров Павел Кириллович | O5: Фролов Сергей Викторович | P5: Петров Павел Кириллович | Q5: 2024-08-30
A6: Новикова Ольга Петровна | B6: Белов Алексей Константинович | C6: Васильев Матвей Романович | D6: =VLOOKUP(B6&C6,J:M,4,0) -> 2024-02-16 | E6: =VLOOKUP(B6&C6,N:Q,4,0) -> 2024-02-16 | F6: =E6-D6 -> 0 | J6: =K6&L6 -> Громова Мария ИльиничнаПетров Илья Михайлович | K6: Громова Мария Ильинична | L6: Петров Илья Михайлович | M6: 2023-09-04 | N6: =O6&P6 -> Белов Алексей КонстантиновичЛебедев Дмитрий Викторович | O6: Белов Алексей Константинович | P6: Лебедев Дмитрий Викторович | Q6: 2024-08-30
A7: Орлов Павел Денисович | B7: Белов Алексей Константинович | C7: Васильев Михаил Павлович | D7: =VLOOKUP(B7&C7,J:M,4,0) -> 2023-11-15 | E7: =VLOOKUP(B7&C7,N:Q,4,0) -> 2023-11-15 | F7: =E7-D7 -> 0 | J7: =K7&L7 -> Яковлев Артем ИгоревичКузнецова Полина Романовна | K7: Яковлев Артем Игоревич | L7: Кузнецова Полина Романовна | M7: 2023-09-04 | N7: =O7&P7 -> Семенова Ирина ВалерьевнаАлексеева Елена Кирилловна | O7: Семенова Ирина Валерьевна | P7: Алексеева Елена Кирилловна | Q7: 2024-08-30
A8: Петров Владимир Кириллович | B8: Белов Алексей Константинович | C8: Васильев Никита Павлович | D8: =VLOOKUP(B8&C8,J:M,4,0) -> 2023-09-21 | E8: =VLOOKUP(B8&C8,N:Q,4,0) -> 2024-08-19 | F8: =E8-D8 -> 333 | J8: =K8&L8 -> Сидорова Елена ВасильевнаЛебедева Полина Ивановна | K8: Сидорова Елена Васильевна | L8: Лебедева Полина Ивановна | M8: 2023-09-04 | N8: =O8&P8 -> Сидорова Елена ВасильевнаОрлов Матвей Алексеевич | O8: Сидорова Елена Васильевна | P8: Орлов Матвей Алексеевич | Q8: 2024-08-29
A9: Семенова Ирина Валерьевна | B9: Белов Алексей Константинович | C9: Васильев Павел Егорович | D9: =VLOOKUP(B9&C9,J:M,4,0) -> 2023-11-01 | E9: =VLOOKUP(B9&C9,N:Q,4,0) -> 2023-11-01 | F9: =E9-D9 -> 0 | J9: =K9&L9 -> Яковлев Артем ИгоревичКузнецов Никита Андреевич | K9: Яковлев Артем Игоревич | L9: Кузнецов Никита Андреевич | M9: 2023-09-04 | N9: =O9&P9 -> Орлов Павел ДенисовичПавлов Павел Юрьевич | O9: Орлов Павел Денисович | P9: Павлов Павел Юрьевич | Q9: 2024-08-29
A10: Сидорова Елена Васильевна | B10: Белов Алексей Константинович | C10: Васильева Людмила Ивановна | D10: =VLOOKUP(B10&C10,J:M,4,0) -> 2024-06-12 | E10: =VLOOKUP(B10&C10,N:Q,4,0) -> 2024-06-12 | F10: =E10-D10 -> 0 | J10: =K10&L10 -> Белов Алексей КонстантиновичКузнецова Мария Юрьевна | K10: Белов Алексей Константинович | L10: Кузнецова Мария Юрьевна | M10: 2023-09-04 | N10: =O10&P10 -> Ткаченко Андрей ОлеговичСмирнов Павел Геннадьевич | O10: Ткаченко Андрей Олегович | P10: Смирнов Павел Геннадьевич | Q10: 2024-08-29
A11: Ткаченко Андрей Олегович | B11: Белов Алексей Константинович | C11: Волков Александр Юрьевич | D11: =VLOOKUP(B11&C11,J:M,4,0) -> 2024-01-15 | E11: =VLOOKUP(B11&C11,N:Q,4,0) -> 2024-01-15 | F11: =E11-D11 -> 0 | J11: =K11&L11 -> Громова Мария ИльиничнаПетрова Вероника Александровна | K11: Громова Мария Ильинична | L11: Петрова Вероника Александровна | M11: 2023-09-04 | N11: =O11&P11 -> Фролов Сергей ВикторовичСидорова Елена Кирилловна | O11: Фролов Сергей Викторович | P11: Сидорова Елена Кирилловна | Q11: 2024-08-29
A12: Фролов Сергей Викторович | B12: Белов Алексей Константинович | C12: Волкова Татьяна Кирилловна | D12: =VLOOKUP(B12&C12,J:M,4,0) -> 2024-05-13 | E12: =VLOOKUP(B12&C12,N:Q,4,0) -> 2024-05-13 | F12: =E12-D12 -> 0 | J12: =K12&L12 -> Яковлев Артем ИгоревичВасильев Матвей Романович | K12: Яковлев Артем Игоревич | L12: Васильев Матвей Романович | M12: 2023-09-04 | N12: =O12&P12 -> Ткаченко Андрей ОлеговичЛебедева Юлия Олеговна | O12: Ткаченко Андрей Олегович | P12: Лебедева Юлия Олеговна | Q12: 2024-08-29
A13: Яковлев Артем Игоревич | B13: Белов Алексей Константинович | C13: Егоров Никита Ильич | D13: =VLOOKUP(B13&C13,J:M,4,0) -> 2024-07-11 | E13: =VLOOKUP(B13&C13,N:Q,4,0) -> 2024-07-11 | F13: =E13-D13 -> 0 | J13: =K13&L13 -> Сидорова Елена ВасильевнаЕгоров Артем Никитич | K13: Сидорова Елена Васильевна | L13: Егоров Артем Никитич | M13: 2023-09-05 | N13: =O13&P13 -> Яковлев Артем ИгоревичИванов Дмитрий Павлович | O13: Яковлев Артем Игоревич | P13: Иванов Дмитрий Павлович | Q13: 2024-08-28
B14: Белов Алексей Константинович | C14: Егорова Ирина Павловна | D14: =VLOOKUP(B14&C14,J:M,4,0) -> 2024-01-11 | E14: =VLOOKUP(B14&C14,N:Q,4,0) -> 2024-05-23 | F14: =E14-D14 -> 133 | J14: =K14&L14 -> Сидорова Елена ВасильевнаОрлова София Станиславовна | K14: Сидорова Елена Васильевна | L14: Орлова София Станиславовна | M14: 2023-09-05 | N14: =O14&P14 -> Сидорова Елена ВасильевнаНовикова Ирина Юрьевна | O14: Сидорова Елена Васильевна | P14: Новикова Ирина Юрьевна | Q14: 2024-08-28
B15: Белов Алексей Константинович | C15: Егорова Наталья Дмитриевна | D15: =VLOOKUP(B15&C15,J:M,4,0) -> 2024-02-01 | E15: =VLOOKUP(B15&C15,N:Q,4,0) -> 2024-08-01 | F15: =E15-D15 -> 182 | J15: =K15&L15 -> Иванова Анна СергеевнаОрлова Ирина Ильинична | K15: Иванова Анна Сергеевна | L15: Орлова Ирина Ильинична | M15: 2023-09-05 | N15: =O15&P15 -> Петров Владимир КирилловичКозлов Роман Александрович | O15: Петров Владимир Кириллович | P15: Козлов Роман Александрович | Q15: 2024-08-27
B16: Белов Алексей Константинович | C16: Иванов Илья Артемович | D16: =VLOOKUP(B16&C16,J:M,4,0) -> 2024-05-20 | E16: =VLOOKUP(B16&C16,N:Q,4,0) -> 2024-05-20 | F16: =E16-D16 -> 0 | J16: =K16&L16 -> Семенова Ирина ВалерьевнаОрлов Георгий Кириллович | K16: Семенова Ирина Валерьевна | L16: Орлов Георгий Кириллович | M16: 2023-09-06 | N16: =O16&P16 -> Иванова Анна СергеевнаНиколаев Егор Романович | O16: Иванова Анна Сергеевна | P16: Николаев Егор Романович | Q16: 2024-08-27
B17: Белов Алексей Константинович | C17: Козлов Роман Александрович | D17: =VLOOKUP(B17&C17,J:M,4,0) -> 2024-01-08 | E17: =VLOOKUP(B17&C17,N:Q,4,0) -> 2024-01-08 | F17: =E17-D17 -> 0 | J17: =K17&L17 -> Семенова Ирина ВалерьевнаПетрова Валерия Павловна | K17: Семенова Ирина Валерьевна | L17: Петрова Валерия Павловна | M17: 2023-09-07 | N17: =O17&P17 -> Новикова Ольга ПетровнаФедоров Владимир Артемович | O17: Новикова Ольга Петровна | P17: Федоров Владимир Артемович | Q17: 2024-08-26
B18: Белов Алексей Константинович | C18: Козлов Роман Владимирович | D18: =VLOOKUP(B18&C18,J:M,4,0) -> 2024-05-23 | E18: =VLOOKUP(B18&C18,N:Q,4,0) -> 2024-05-23 | F18: =E18-D18 -> 0 | J18: =K18&L18 -> Иванова Анна СергеевнаФедоров Илья Владимирович | K18: Иванова Анна Сергеевна | L18: Федоров Илья Владимирович | M18: 2023-09-07 | N18: =O18&P18 -> Ткаченко Андрей ОлеговичЛебедев Дмитрий Викторович | O18: Ткаченко Андрей Олегович | P18: Лебедев Дмитрий Викторович | Q18: 2024-08-26
B19: Белов Алексей Константинович | C19: Козлова Екатерина Олеговна | D19: =VLOOKUP(B19&C19,J:M,4,0) -> 2024-06-10 | E19: =VLOOKUP(B19&C19,N:Q,4,0) -> 2024-06-10 | F19: =E19-D19 -> 0 | J19: =K19&L19 -> Громова Мария ИльиничнаФедоров Илья Владимирович | K19: Громова Мария Ильинична | L19: Федоров Илья Владимирович | M19: 2023-09-07 | N19: =O19&P19 -> Иванова Анна СергеевнаЕгорова Ирина Павловна | O19: Иванова Анна Сергеевна | P19: Егорова Ирина Павловна | Q19: 2024-08-26
B20: Белов Алексей Константинович | C20: Кузнецов Георгий Кириллович | D20: =VLOOKUP(B20&C20,J:M,4,0) -> 2023-12-25 | E20: =VLOOKUP(B20&C20,N:Q,4,0) -> 2023-12-25 | F20: =E20-D20 -> 0 | J20: =K20&L20 -> Ткаченко Андрей ОлеговичСтепанова Полина Артемовна | K20: Ткаченко Андрей Олегович | L20: Степанова Полина Артемовна | M20: 2023-09-07 | N20: =O20&P20 -> Громова Мария ИльиничнаМорозов Артем Александрович | O20: Громова Мария Ильинична | P20: Морозов Артем Александрович | Q20: 2024-08-26
B21: Белов Алексей Константинович | C21: Кузнецов Михаил Артемович | D21: =VLOOKUP(B21&C21,J:M,4,0) -> 2024-05-31 | E21: =VLOOKUP(B21&C21,N:Q,4,0) -> 2024-05-31 | F21: =E21-D21 -> 0 | J21: =K21&L21 -> Громова Мария ИльиничнаНовиков Михаил Владимирович | K21: Громова Мария Ильинична | L21: Новиков Михаил Владимирович | M21: 2023-09-07 | N21: =O21&P21 -> Белов Алексей КонстантиновичКузнецов Сергей Кириллович | O21: Белов Алексей Константинович | P21: Кузнецов Сергей Кириллович | Q21: 2024-08-26
B22: Белов Алексей Константинович | C22: Кузнецов Сергей Кириллович | D22: =VLOOKUP(B22&C22,J:M,4,0) -> 2024-08-26 | E22: =VLOOKUP(B22&C22,N:Q,4,0) -> 2024-08-26 | F22: =E22-D22 -> 0 | J22: =K22&L22 -> Громова Мария ИльиничнаИванов Александр Павлович | K22: Громова Мария Ильинична | L22: Иванов Александр Павлович | M22: 2023-09-08 | N22: =O22&P22 -> Кузнецов Дмитрий ЛьвовичПавлова София Владимировна | O22: Кузнецов Дмитрий Львович | P22: Павлова София Владимировна | Q22: 2024-08-26
B23: Белов Алексей Константинович | C23: Кузнецова Дарья Дмитриевна | D23: =VLOOKUP(B23&C23,J:M,4,0) -> 2024-04-08 | E23: =VLOOKUP(B23&C23,N:Q,4,0) -> 2024-04-08 | F23: =E23-D23 -> 0 | J23: =K23&L23 -> Кузнецов Дмитрий ЛьвовичПетров Иван Артемович | K23: Кузнецов Дмитрий Львович | L23: Петров Иван Артемович | M23: 2023-09-08 | N23: =O23&P23 -> Громова Мария ИльиничнаПавлова Екатерина Егоровна | O23: Громова Мария Ильинична | P23: Павлова Екатерина Егоровна | Q23: 2024-08-26
B24: Белов Алексей Константинович | C24: Кузнецова Ирина Владимировна | D24: =VLOOKUP(B24&C24,J:M,4,0) -> 2024-01-18 | E24: =VLOOKUP(B24&C24,N:Q,4,0) -> 2024-08-20 | F24: =E24-D24 -> 215 | J24: =K24&L24 -> Фролов Сергей ВикторовичФедоров Роман Дмитриевич | K24: Фролов Сергей Викторович | L24: Федоров Роман Дмитриевич | M24: 2023-09-08 | N24: =O24&P24 -> Новикова Ольга ПетровнаНовикова Анна Геннадьевна | O24: Новикова Ольга Петровна | P24: Новикова Анна Геннадьевна | Q24: 2024-08-23
B25: Белов Алексей Константинович | C25: Кузнецова Мария Юрьевна | D25: =VLOOKUP(B25&C25,J:M,4,0) -> 2023-09-04 | E25: =VLOOKUP(B25&C25,N:Q,4,0) -> 2023-09-04 | F25: =E25-D25 -> 0 | J25: =K25&L25 -> Кузнецов Дмитрий ЛьвовичНовикова Людмила Кирилловна | K25: Кузнецов Дмитрий Львович | L25: Новикова Людмила Кирилловна | M25: 2023-09-08 | N25: =O25&P25 -> Громова Мария ИльиничнаЕгоров Константин Ильич | O25: Громова Мария Ильинична | P25: Егоров Константин Ильич | Q25: 2024-08-21
... B815: Яковлев Артем Игоревич | C815: Федоров Дмитрий Михайлович | D815: =VLOOKUP(B815&C815,J:M,4,0) -> 2024-04-30 | E815: =VLOOKUP(B815&C815,N:Q,4,0) -> 2024-04-30 | F815: =E815-D815 -> 0 | J815: =K815&L815 -> Ткаченко Андрей ОлеговичЕгоров Никита Ильич | K815: Ткаченко Андрей Олегович | L815: Егоров Никита Ильич | M815: 2024-06-18 | N815: =O815&P815 -> Петров Владимир КирилловичПетров Илья Андреевич | O815: Петров Владимир Кириллович | P815: Петров Илья Андреевич | Q815: 2023-11-03
J816: =K816&L816 -> Громова Мария ИльиничнаВасильева София Александровна | K816: Громова Мария Ильинична | L816: Васильева София Александровна | M816: 2024-06-18 | N816: =O816&P816 -> Новикова Ольга ПетровнаПетров Илья Михайлович | O816: Новикова Ольга Петровна | P816: Петров Илья Михайлович | Q816: 2023-11-02
J817: =K817&L817 -> Петров Владимир КирилловичНовиков Михаил Владимирович | K817: Петров Владимир Кириллович | L817: Новиков Михаил Владимирович | M817: 2024-06-18 | N817: =O817&P817 -> Ткаченко Андрей ОлеговичМорозов Андрей Никитич | O817: Ткаченко Андрей Олегович | P817: Морозов Андрей Никитич | Q817: 2023-11-02
J818: =K818&L818 -> Ткаченко Андрей ОлеговичВасильев Матвей Андреевич | K818: Ткаченко Андрей Олегович | L818: Васильев Матвей Андреевич | M818: 2024-06-19 | N818: =O818&P818 -> Орлов Павел ДенисовичОрлова Юлия Алексеевна | O818: Орлов Павел Денисович | P818: Орлова Юлия Алексеевна | Q818: 2023-11-01
J819: =K819&L819 -> Сидорова Елена ВасильевнаНиколаева Полина Егоровна | K819: Сидорова Елена Васильевна | L819: Николаева Полина Егоровна | M819: 2024-06-19 | N819: =O819&P819 -> Белов Алексей КонстантиновичВасильев Павел Егорович | O819: Белов Алексей Константинович | P819: Васильев Павел Егорович | Q819: 2023-11-01
J820: =K820&L820 -> Сидорова Елена ВасильевнаКозлов Роман Александрович | K820: Сидорова Елена Васильевна | L820: Козлов Роман Александрович | M820: 2024-06-19 | N820: =O820&P820 -> Громова Мария ИльиничнаМорозова Валерия Ильинична | O820: Громова Мария Ильинична | P820: Морозова Валерия Ильинична | Q820: 2023-11-01
J821: =K821&L821 -> Семенова Ирина ВалерьевнаМорозов Максим Андреевич | K821: Семенова Ирина Валерьевна | L821: Морозов Максим Андреевич | M821: 2024-06-19 | N821: =O821&P821 -> Ткаченко Андрей ОлеговичПавлов Роман Владимирович | O821: Ткаченко Андрей Олегович | P821: Павлов Роман Владимирович | Q821: 2023-10-31
J822: =K822&L822 -> Белов Алексей КонстантиновичПетров Павел Кириллович | K822: Белов Алексей Константинович | L822: Петров Павел Кириллович | M822: 2024-06-20 | N822: =O822&P822 -> Иванова Анна СергеевнаСмирнова Юлия Олеговна | O822: Иванова Анна Сергеевна | P822: Смирнова Юлия Олеговна | Q822: 2023-10-30
J823: =K823&L823 -> Яковлев Артем ИгоревичКозлов Илья Егорович | K823: Яковлев Артем Игоревич | L823: Козлов Илья Егорович | M823: 2024-06-20 | N823: =O823&P823 -> Фролов Сергей ВикторовичВасильев Никита Павлович | O823: Фролов Сергей Викторович | P823: Васильев Никита Павлович | Q823: 2023-10-30
J824: =K824&L824 -> Громова Мария ИльиничнаМорозова Мария Дмитриевна | K824: Громова Мария Ильинична | L824: Морозова Мария Дмитриевна | M824: 2024-06-21 | N824: =O824&P824 -> Петров Владимир КирилловичСмирнов Дмитрий Никитич | O824: Петров Владимир Кириллович | P824: Смирнов Дмитрий Никитич | Q824: 2023-10-30
J825: =K825&L825 -> Новикова Ольга ПетровнаСтепанова Полина Артемовна | K825: Новикова Ольга Петровна | L825: Степанова Полина Артемовна | M825: 2024-06-21 | N825: =O825&P825 -> Новикова Ольга ПетровнаСидоров Дмитрий Кириллович | O825: Новикова Ольга Петровна | P825: Сидоров Дмитрий Кириллович | Q825: 2023-10-30
J826: =K826&L826 -> Новикова Ольга ПетровнаПетров Илья Андреевич | K826: Новикова Ольга Петровна | L826: Петров Илья Андреевич | M826: 2024-06-24 | N826: =O826&P826 -> Фролов Сергей ВикторовичОрлов Матвей Алексеевич | O826: Фролов Сергей Викторович | P826: Орлов Матвей Алексеевич | Q826: 2023-10-30
J827: =K827&L827 -> Яковлев Артем ИгоревичЛебедева Анна Викторовна | K827: Яковлев Артем Игоревич | L827: Лебедева Анна Викторовна | M827: 2024-06-24 | N827: =O827&P827 -> Орлов Павел ДенисовичОрлов Александр Иванович | O827: Орлов Павел Денисович | P827: Орлов Александр Иванович | Q827: 2023-10-30
... J1001: =K1001&L1001 -> Ткаченко Андрей ОлеговичВасильева Александра Александровна | K1001: Ткаченко Андрей Олегович | L1001: Васильева Александра Александровна | M1001: 2024-09-02 | N1001: =O1001&P1001 -> Семенова Ирина ВалерьевнаЕгорова Юлия Алексеевна | O1001: Семенова Ирина Валерьевна | P1001: Егорова Юлия Алексеевна | Q1001: 2023-09-01

Sheet Задача 1.2
A1: ФИО менеджера | B1: ФИО клиента | C1: Кол-во
A2: Белов Алексей Константинович | B2: Васильев Никита Павлович | C2: 333
A3: Яковлев Артем Игоревич | B3: Орлов Александр Иванович | C3: 329
A4: Новикова Ольга Петровна | B4: Орлова Полина Олеговна | C4: 323
A5: Новикова Ольга Петровна | B5: Иванов Илья Артемович | C5: 320
A6: Яковлев Артем Игоревич | B6: Кузнецов Никита Андреевич | C6: 315
A7: Белов Алексей Константинович | B7: Петров Алексей Сергеевич | C7: 309
A8: Сидорова Елена Васильевна | B8: Егоров Максим Олегович | C8: 302
A9: Орлов Павел Денисович | B9: Лебедева Анна Викторовна | C9: 300
A10: Сидорова Елена Васильевна | B10: Орлов Александр Иванович | C10: 289
A11: Яковлев Артем Игоревич | B11: Лебедев Артем Кириллович | C11: 287
A12: Петров Владимир Кириллович | B12: Петров Илья Андреевич | C12: 286
A13: Ткаченко Андрей Олегович | B13: Петрова Вероника Александровна | C13: 280
... A815: Яковлев Артем Игоревич | B815: Федоров Дмитрий Михайлович | C815: 0

Sheet Задача 2
A1: ФИО клиента | B1: Проекты | C1: Сумма | G1: Менеджеры
A2: Алексеев Матвей Александрович | B2: 2 | C2: 100664 | G2: =COUNTIF('Задача 1'!C:C,'Задача 2'!A2) -> 3
A3: Алексеева Елена Кирилловна | B3: 3 | C3: 530673 | G3: =COUNTIF('Задача 1'!C:C,'Задача 2'!A3) -> 5
A4: Алексеева Ольга Сергеевна | B4: 3 | C4: 446016 | G4: =COUNTIF('Задача 1'!C:C,'Задача 2'!A4) -> 1
A5: Алексеева Светлана Станиславовна | B5: 6 | C5: 451314 | G5: =COUNTIF('Задача 1'!C:C,'Задача 2'!A5) -> 8
A6: Васильев Илья Александрович | B6: 2 | C6: 87378 | G6: =COUNTIF('Задача 1'!C:C,'Задача 2'!A6) -> 2
A7: Васильев Константин Алексеевич | B7: 3 | C7: 226507 | G7: =COUNTIF('Задача 1'!C:C,'Задача 2'!A7) -> 2
A8: Васильев Константин Геннадьевич | B8: 5 | C8: 168973 | G8: =COUNTIF('Задача 1'!C:C,'Задача 2'!A8) -> 7
A9: Васильев Матвей Андреевич | B9: 5 | C9: 209335 | G9: =COUNTIF('Задача 1'!C:C,'Задача 2'!A9) -> 5
A10: Васильев Матвей Геннадьевич | B10: 6 | C10: 157987 | G10: =COUNTIF('Задача 1'!C:C,'Задача 2'!A10) -> 5
A11: Васильев Матвей Романович | B11: 4 | C11: 439379 | G11: =COUNTIF('Задача 1'!C:C,'Задача 2'!A11) -> 5
A12: Васильев Михаил Павлович | B12: 7 | C12: 210364 | G12: =COUNTIF('Задача 1'!C:C,'Задача 2'!A12) -> 4
A13: Васильев Никита Павлович | B13: 7 | C13: 202292 | G13: =COUNTIF('Задача 1'!C:C,'Задача 2'!A13) -> 5
... A197: Федорова Ольга Викторовна | B197: 7 | C197: 351667 | G197: =COUNTIF('Задача 1'!C:C,'Задача 2'!A197) -> 5

Sheet Задача 3.1
A1: ФИО менеджера | B1: ФИО клиента | C1: Дата сделки | D1: Сумма сделки | E1: NPS | F1: Год | G1: Месяц | H1: ГМ
A2: Ткаченко Андрей Олегович | B2: Лебедева Виктория Дмитриевна | C2: 2023-09-01 | D2: 31810 | E2: 5 | F2: =YEAR(C2) -> 2023 | G2: =MONTH(C2) -> 9 | H2: =F2&"-"&G2 -> 2023-9
A3: Яковлев Артем Игоревич | B3: Семенов Дмитрий Олегович | C3: 2023-09-01 | D3: 79983 | E3: 8 | F3: =YEAR(C3) -> 2023 | G3: =MONTH(C3) -> 9 | H3: =F3&"-"&G3 -> 2023-9
A4: Кузнецов Дмитрий Львович | B4: Новикова Екатерина Ивановна | C4: 2023-09-01 | D4: 65103 | E4: 7 | F4: =YEAR(C4) -> 2023 | G4: =MONTH(C4) -> 9 | H4: =F4&"-"&G4 -> 2023-9
A5: Семенова Ирина Валерьевна | B5: Егорова Юлия Алексеевна | C5: 2023-09-01 | D5: 45916 | E5: 8 | F5: =YEAR(C5) -> 2023 | G5: =MONTH(C5) -> 9 | H5: =F5&"-"&G5 -> 2023-9
A6: Громова Мария Ильинична | B6: Петров Илья Михайлович | C6: 2023-09-04 | D6: 26479 | E6: 7 | F6: =YEAR(C6) -> 2023 | G6: =MONTH(C6) -> 9 | H6: =F6&"-"&G6 -> 2023-9
A7: Яковлев Артем Игоревич | B7: Кузнецова Полина Романовна | C7: 2023-09-04 | D7: 65924 | E7: 8 | F7: =YEAR(C7) -> 2023 | G7: =MONTH(C7) -> 9 | H7: =F7&"-"&G7 -> 2023-9
A8: Сидорова Елена Васильевна | B8: Лебедева Полина Ивановна | C8: 2023-09-04 | D8: 84442 | E8: 5 | F8: =YEAR(C8) -> 2023 | G8: =MONTH(C8) -> 9 | H8: =F8&"-"&G8 -> 2023-9
A9: Яковлев Артем Игоревич | B9: Кузнецов Никита Андреевич | C9: 2023-09-04 | D9: 36848 | E9: 6 | F9: =YEAR(C9) -> 2023 | G9: =MONTH(C9) -> 9 | H9: =F9&"-"&G9 -> 2023-9
A10: Белов Алексей Константинович | B10: Кузнецова Мария Юрьевна | C10: 2023-09-04 | D10: 27991 | E10: 7 | F10: =YEAR(C10) -> 2023 | G10: =MONTH(C10) -> 9 | H10: =F10&"-"&G10 -> 2023-9
A11: Громова Мария Ильинична | B11: Петрова Вероника Александровна | C11: 2023-09-04 | D11: 21080 | E11: 9 | F11: =YEAR(C11) -> 2023 | G11: =MONTH(C11) -> 9 | H11: =F11&"-"&G11 -> 2023-9
A12: Яковлев Артем Игоревич | B12: Васильев Матвей Романович | C12: 2023-09-04 | D12: 13650 | E12: 4 | F12: =YEAR(C12) -> 2023 | G12: =MONTH(C12) -> 9 | H12: =F12&"-"&G12 -> 2023-9
A13: Сидорова Елена Васильевна | B13: Егоров Артем Никитич | C13: 2023-09-05 | D13: 36816 | E13: 2 | F13: =YEAR(C13) -> 2023 | G13: =MONTH(C13) -> 9 | H13: =F13&"-"&G13 -> 2023-9
... A1001: Ткаченко Андрей Олегович | B1001: Васильева Александра Александровна | C1001: 2024-09-02 | D1001: 49150 | E1001: 8 | F1001: =YEAR(C1001) -> 2024 | G1001: =MONTH(C1001) -> 9 | H1001: =F1001&"-"&G1001 -> 2024-9

Sheet Задача 3
B1: 2023-9 | C1: 2023-10 | D1: 2023-11 | E1: 2023-12 | F1: 2024-1 | G1: 2024-2 | H1: 2024-3 | I1: 2024-4 | J1: 2024-5 | K1: 2024-6 | L1: 2024-7 | M1: 2024-8 | N1: 2024-9 | Q1: ФИО менеджера | R1: ФИО клиента | S1: Дата сделки | T1: Сумма сделки | U1: NPS | V1: Год | W1: Месяц | X1: Год
A2: Белов Алексей Константинович | B2: =COUNTIFS($Q:$Q,$A2,$X:$X,B$1) -> 7 | C2: =COUNTIFS($Q:$Q,$A2,$X:$X,C$1) -> 5 | D2: =COUNTIFS($Q:$Q,$A2,$X:$X,D$1) -> 8 | E2: =COUNTIFS($Q:$Q,$A2,$X:$X,E$1) -> 5 | F2: =COUNTIFS($Q:$Q,$A2,$X:$X,F$1) -> 11 | G2: =COUNTIFS($Q:$Q,$A2,$X:$X,G$1) -> 8 | H2: =COUNTIFS($Q:$Q,$A2,$X:$X,H$1) -> 1 | I2: =COUNTIFS($Q:$Q,$A2,$X:$X,I$1) -> 12 | ... N2: =COUNTIFS($Q:$Q,$A2,$X:$X,N$1) -> 0 | Q2: Ткаченко Андрей Олегович | R2: Лебедева Виктория Дмитриевна | S2: 2023-09-01 | T2: 31810 | U2: 5 | V2: =YEAR(S2) -> 2023 | W2: =MONTH(S2) -> 9 | X2: =V2&"-"&W2 -> 2023-9
A3: Громова Мария Ильинична | B3: =COUNTIFS($Q:$Q,$A3,$X:$X,B$1) -> 7 | C3: =COUNTIFS($Q:$Q,$A3,$X:$X,C$1) -> 4 | D3: =COUNTIFS($Q:$Q,$A3,$X:$X,D$1) -> 10 | E3: =COUNTIFS($Q:$Q,$A3,$X:$X,E$1) -> 6 | F3: =COUNTIFS($Q:$Q,$A3,$X:$X,F$1) -> 14 | G3: =COUNTIFS($Q:$Q,$A3,$X:$X,G$1) -> 5 | H3: =COUNTIFS($Q:$Q,$A3,$X:$X,H$1) -> 8 | I3: =COUNTIFS($Q:$Q,$A3,$X:$X,I$1) -> 8 | ... N3: =COUNTIFS($Q:$Q,$A3,$X:$X,N$1) -> 0 | Q3: Яковлев Артем Игоревич | R3: Семенов Дмитрий Олегович | S3: 2023-09-01 | T3: 79983 | U3: 8 | V3: =YEAR(S3) -> 2023 | W3: =MONTH(S3) -> 9 | X3: =V3&"-"&W3 -> 2023-9
A4: Иванова Анна Сергеевна | B4: =COUNTIFS($Q:$Q,$A4,$X:$X,B$1) -> 10 | C4: =COUNTIFS($Q:$Q,$A4,$X:$X,C$1) -> 5 | D4: =COUNTIFS($Q:$Q,$A4,$X:$X,D$1) -> 6 | E4: =COUNTIFS($Q:$Q,$A4,$X:$X,E$1) -> 3 | F4: =COUNTIFS($Q:$Q,$A4,$X:$X,F$1) -> 4 | G4: =COUNTIFS($Q:$Q,$A4,$X:$X,G$1) -> 6 | H4: =COUNTIFS($Q:$Q,$A4,$X:$X,H$1) -> 6 | I4: =COUNTIFS($Q:$Q,$A4,$X:$X,I$1) -> 7 | ... N4: =COUNTIFS($Q:$Q,$A4,$X:$X,N$1) -> 1 | Q4: Кузнецов Дмитрий Львович | R4: Новикова Екатерина Ивановна | S4: 2023-09-01 | T4: 65103 | U4: 7 | V4: =YEAR(S4) -> 2023 | W4: =MONTH(S4) -> 9 | X4: =V4&"-"&W4 -> 2023-9
A5: Кузнецов Дмитрий Львович | B5: =COUNTIFS($Q:$Q,$A5,$X:$X,B$1) -> 5 | C5: =COUNTIFS($Q:$Q,$A5,$X:$X,C$1) -> 7 | D5: =COUNTIFS($Q:$Q,$A5,$X:$X,D$1) -> 6 | E5: =COUNTIFS($Q:$Q,$A5,$X:$X,E$1) -> 9 | F5: =COUNTIFS($Q:$Q,$A5,$X:$X,F$1) -> 5 | G5: =COUNTIFS($Q:$Q,$A5,$X:$X,G$1) -> 12 | H5: =COUNTIFS($Q:$Q,$A5,$X:$X,H$1) -> 2 | I5: =COUNTIFS($Q:$Q,$A5,$X:$X,I$1) -> 7 | ... N5: =COUNTIFS($Q:$Q,$A5,$X:$X,N$1) -> 0 | Q5: Семенова Ирина Валерьевна | R5: Егорова Юлия Алексеевна | S5: 2023-09-01 | T5: 45916 | U5: 8 | V5: =YEAR(S5) -> 2023 | W5: =MONTH(S5) -> 9 | X5: =V5&"-"&W5 -> 2023-9
A6: Новикова Ольга Петровна | B6: =COUNTIFS($Q:$Q,$A6,$X:$X,B$1) -> 9 | C6: =COUNTIFS($Q:$Q,$A6,$X:$X,C$1) -> 13 | D6: =COUNTIFS($Q:$Q,$A6,$X:$X,D$1) -> 6 | E6: =COUNTIFS($Q:$Q,$A6,$X:$X,E$1) -> 6 | F6: =COUNTIFS($Q:$Q,$A6,$X:$X,F$1) -> 7 | G6: =COUNTIFS($Q:$Q,$A6,$X:$X,G$1) -> 9 | H6: =COUNTIFS($Q:$Q,$A6,$X:$X,H$1) -> 3 | I6: =COUNTIFS($Q:$Q,$A6,$X:$X,I$1) -> 5 | ... N6: =COUNTIFS($Q:$Q,$A6,$X:$X,N$1) -> 0 | Q6: Громова Мария Ильинична | R6: Петров Илья Михайлович | S6: 2023-09-04 | T6: 26479 | U6: 7 | V6: =YEAR(S6) -> 2023 | W6: =MONTH(S6) -> 9 | X6: =V6&"-"&W6 -> 2023-9
A7: Орлов Павел Денисович | B7: =COUNTIFS($Q:$Q,$A7,$X:$X,B$1) -> 7 | C7: =COUNTIFS($Q:$Q,$A7,$X:$X,C$1) -> 10 | D7: =COUNTIFS($Q:$Q,$A7,$X:$X,D$1) -> 8 | E7: =COUNTIFS($Q:$Q,$A7,$X:$X,E$1) -> 9 | F7: =COUNTIFS($Q:$Q,$A7,$X:$X,F$1) -> 7 | G7: =COUNTIFS($Q:$Q,$A7,$X:$X,G$1) -> 4 | H7: =COUNTIFS($Q:$Q,$A7,$X:$X,H$1) -> 3 | I7: =COUNTIFS($Q:$Q,$A7,$X:$X,I$1) -> 7 | ... N7: =COUNTIFS($Q:$Q,$A7,$X:$X,N$1) -> 0 | Q7: Яковлев Артем Игоревич | R7: Кузнецова Полина Романовна | S7: 2023-09-04 | T7: 65924 | U7: 8 | V7: =YEAR(S7) -> 2023 | W7: =MONTH(S7) -> 9 | X7: =V7&"-"&W7 -> 2023-9
A8: Петров Владимир Кириллович | B8: =COUNTIFS($Q:$Q,$A8,$X:$X,B$1) -> 6 | C8: =COUNTIFS($Q:$Q,$A8,$X:$X,C$1) -> 5 | D8: =COUNTIFS($Q:$Q,$A8,$X:$X,D$1) -> 10 | E8: =COUNTIFS($Q:$Q,$A8,$X:$X,E$1) -> 7 | F8: =COUNTIFS($Q:$Q,$A8,$X:$X,F$1) -> 10 | G8: =COUNTIFS($Q:$Q,$A8,$X:$X,G$1) -> 10 | H8: =COUNTIFS($Q:$Q,$A8,$X:$X,H$1) -> 3 | I8: =COUNTIFS($Q:$Q,$A8,$X:$X,I$1) -> 9 | ... N8: =COUNTIFS($Q:$Q,$A8,$X:$X,N$1) -> 0 | Q8: Сидорова Елена Васильевна | R8: Лебедева Полина Ивановна | S8: 2023-09-04 | T8: 84442 | U8: 5 | V8: =YEAR(S8) -> 2023 | W8: =MONTH(S8) -> 9 | X8: =V8&"-"&W8 -> 2023-9
A9: Семенова Ирина Валерьевна | B9: =COUNTIFS($Q:$Q,$A9,$X:$X,B$1) -> 6 | C9: =COUNTIFS($Q:$Q,$A9,$X:$X,C$1) -> 5 | D9: =COUNTIFS($Q:$Q,$A9,$X:$X,D$1) -> 6 | E9: =COUNTIFS($Q:$Q,$A9,$X:$X,E$1) -> 5 | F9: =COUNTIFS($Q:$Q,$A9,$X:$X,F$1) -> 8 | G9: =COUNTIFS($Q:$Q,$A9,$X:$X,G$1) -> 8 | H9: =COUNTIFS($Q:$Q,$A9,$X:$X,H$1) -> 1 | I9: =COUNTIFS($Q:$Q,$A9,$X:$X,I$1) -> 5 | ... N9: =COUNTIFS($Q:$Q,$A9,$X:$X,N$1) -> 1 | Q9: Яковлев Артем Игоревич | R9: Кузнецов Никита Андреевич | S9: 2023-09-04 | T9: 36848 | U9: 6 | V9: =YEAR(S9) -> 2023 | W9: =MONTH(S9) -> 9 | X9: =V9&"-"&W9 -> 2023-9
A10: Сидорова Елена Васильевна | B10: =COUNTIFS($Q:$Q,$A10,$X:$X,B$1) -> 11 | C10: =COUNTIFS($Q:$Q,$A10,$X:$X,C$1) -> 7 | D10: =COUNTIFS($Q:$Q,$A10,$X:$X,D$1) -> 6 | E10: =COUNTIFS($Q:$Q,$A10,$X:$X,E$1) -> 1 | F10: =COUNTIFS($Q:$Q,$A10,$X:$X,F$1) -> 11 | G10: =COUNTIFS($Q:$Q,$A10,$X:$X,G$1) -> 7 | H10: =COUNTIFS($Q:$Q,$A10,$X:$X,H$1) -> 7 | I10: =COUNTIFS($Q:$Q,$A10,$X:$X,I$1) -> 6 | ... N10: =COUNTIFS($Q:$Q,$A10,$X:$X,N$1) -> 0 | Q10: Белов Алексей Константинович | R10: Кузнецова Мария Юрьевна | S10: 2023-09-04 | T10: 27991 | U10: 7 | V10: =YEAR(S10) -> 2023 | W10: =MONTH(S10) -> 9 | X10: =V10&"-"&W10 -> 2023-9
A11: Ткаченко Андрей Олегович | B11: =COUNTIFS($Q:$Q,$A11,$X:$X,B$1) -> 4 | C11: =COUNTIFS($Q:$Q,$A11,$X:$X,C$1) -> 11 | D11: =COUNTIFS($Q:$Q,$A11,$X:$X,D$1) -> 9 | E11: =COUNTIFS($Q:$Q,$A11,$X:$X,E$1) -> 5 | F11: =COUNTIFS($Q:$Q,$A11,$X:$X,F$1) -> 6 | G11: =COUNTIFS($Q:$Q,$A11,$X:$X,G$1) -> 2 | H11: =COUNTIFS($Q:$Q,$A11,$X:$X,H$1) -> 3 | I11: =COUNTIFS($Q:$Q,$A11,$X:$X,I$1) -> 7 | ... N11: =COUNTIFS($Q:$Q,$A11,$X:$X,N$1) -> 1 | Q11: Громова Мария Ильинична | R11: Петрова Вероника Александровна | S11: 2023-09-04 | T11: 21080 | U11: 9 | V11: =YEAR(S11) -> 2023 | W11: =MONTH(S11) -> 9 | X11: =V11&"-"&W11 -> 2023-9
A12: Фролов Сергей Викторович | B12: =COUNTIFS($Q:$Q,$A12,$X:$X,B$1) -> 8 | C12: =COUNTIFS($Q:$Q,$A12,$X:$X,C$1) -> 9 | D12: =COUNTIFS($Q:$Q,$A12,$X:$X,D$1) -> 6 | E12: =COUNTIFS($Q:$Q,$A12,$X:$X,E$1) -> 3 | F12: =COUNTIFS($Q:$Q,$A12,$X:$X,F$1) -> 5 | G12: =COUNTIFS($Q:$Q,$A12,$X:$X,G$1) -> 9 | H12: =COUNTIFS($Q:$Q,$A12,$X:$X,H$1) -> 11 | I12: =COUNTIFS($Q:$Q,$A12,$X:$X,I$1) -> 5 | ... N12: =COUNTIFS($Q:$Q,$A12,$X:$X,N$1) -> 0 | Q12: Яковлев Артем Игоревич | R12: Васильев Матвей Романович | S12: 2023-09-04 | T12: 13650 | U12: 4 | V12: =YEAR(S12) -> 2023 | W12: =MONTH(S12) -> 9 | X12: =V12&"-"&W12 -> 2023-9
A13: Яковлев Артем Игоревич | B13: =COUNTIFS($Q:$Q,$A13,$X:$X,B$1) -> 13 | C13: =COUNTIFS($Q:$Q,$A13,$X:$X,C$1) -> 7 | D13: =COUNTIFS($Q:$Q,$A13,$X:$X,D$1) -> 5 | E13: =COUNTIFS($Q:$Q,$A13,$X:$X,E$1) -> 12 | F13: =COUNTIFS($Q:$Q,$A13,$X:$X,F$1) -> 10 | G13: =COUNTIFS($Q:$Q,$A13,$X:$X,G$1) -> 4 | H13: =COUNTIFS($Q:$Q,$A13,$X:$X,H$1) -> 8 | I13: =COUNTIFS($Q:$Q,$A13,$X:$X,I$1) -> 10 | ... N13: =COUNTIFS($Q:$Q,$A13,$X:$X,N$1) -> 0 | Q13: Сидорова Елена Васильевна | R13: Егоров Артем Никитич | S13: 2023-09-05 | T13: 36816 | U13: 2 | V13: =YEAR(S13) -> 2023 | W13: =MONTH(S13) -> 9 | X13: =V13&"-"&W13 -> 2023-9
Q14: Сидорова Елена Васильевна | R14: Орлова София Станиславовна | S14: 2023-09-05 | T14: 17474 | U14: 2 | V14: =YEAR(S14) -> 2023 | W14: =MONTH(S14) -> 9 | X14: =V14&"-"&W14 -> 2023-9
Q15: Иванова Анна Сергеевна | R15: Орлова Ирина Ильинична | S15: 2023-09-05 | T15: 30692 | U15: 5 | V15: =YEAR(S15) -> 2023 | W15: =MONTH(S15) -> 9 | X15: =V15&"-"&W15 -> 2023-9
Q16: Семенова Ирина Валерьевна | R16: Орлов Георгий Кириллович | S16: 2023-09-06 | T16: 44283 | U16: 6 | V16: =YEAR(S16) -> 2023 | W16: =MONTH(S16) -> 9 | X16: =V16&"-"&W16 -> 2023-9
B17: 2023-9 | C17: 2023-10 | D17: 2023-11 | E17: 2023-12 | F17: 2024-1 | G17: 2024-2 | H17: 2024-3 | I17: 2024-4 | J17: 2024-5 | K17: 2024-6 | L17: 2024-7 | M17: 2024-8 | N17: 2024-9 | Q17: Семенова Ирина Валерьевна | R17: Петрова Валерия Павловна | S17: 2023-09-07 | T17: 54765 | U17: 8 | V17: =YEAR(S17) -> 2023 | W17: =MONTH(S17) -> 9 | X17: =V17&"-"&W17 -> 2023-9
A18: Белов Алексей Константинович | B18: =IFERROR((COUNTIFS($Q:$Q,$A18,$X:$X,B$17,$U:$U,">=9") - COUNTIFS($Q:$Q,$A18,$X:$X,B$17,$U:$U,"<=6"))/COUNTIFS($Q:$Q,$A18,$X:$X,B$17,$U:$U,">=0"),"") -> -0.14285714 | C18: =IFERROR((COUNTIFS($Q:$Q,$A18,$X:$X,C$17,$U:$U,">=9") - COUNTIFS($Q:$Q,$A18,$X:$X,C$17,$U:$U,"<=6"))/COUNTIFS($Q:$Q,$A18,$X:$X,C$17,$U:$U,">=0"),"") -> 0 | D18: =IFERROR((COUNTIFS($Q:$Q,$A18,$X:$X,D$17,$U:$U,">=9") - COUNTIFS($Q:$Q,$A18,$X:$X,D$17,$U:$U,"<=6"))/COUNTIFS($Q:$Q,$A18,$X:$X,D$17,$U:$U,">=0"),"") -> -0.25 | E18: =IFERROR((COUNTIFS($Q:$Q,$A18,$X:$X,E$17,$U:$U,">=9") - COUNTIFS($Q:$Q,$A18,$X:$X,E$17,$U:$U,"<=6"))/COUNTIFS($Q:$Q,$A18,$X:$X,E$17,$U:$U,">=0"),"") -> -0.6 | F18: =IFERROR((COUNTIFS($Q:$Q,$A18,$X:$X,F$17,$U:$U,">=9") - COUNTIFS($Q:$Q,$A18,$X:$X,F$17,$U:$U,"<=6"))/COUNTIFS($Q:$Q,$A18,$X:$X,F$17,$U:$U,">=0"),"") -> -0.18181818 | G18: =IFERROR((COUNTIFS($Q:$Q,$A18,$X:$X,G$17,$U:$U,">=9") - COUNTIFS($Q:$Q,$A18,$X:$X,G$17,$U:$U,"<=6"))/COUNTIFS($Q:$Q,$A18,$X:$X,G$17,$U:$U,">=0"),"") -> -0.25 | H18: =IFERROR((COUNTIFS($Q:$Q,$A18,$X:$X,H$17,$U:$U,">=9") - COUNTIFS($Q:$Q,$A18,$X:$X,H$17,$U:$U,"<=6"))/COUNTIFS($Q:$Q,$A18,$X:$X,H$17,$U:$U,">=0"),"") -> 1 | I18: =IFERROR((COUNTIFS($Q:$Q,$A18,$X:$X,I$17,$U:$U,">=9") - COUNTIFS($Q:$Q,$A18,$X:$X,I$17,$U:$U,"<=6"))/COUNTIFS($Q:$Q,$A18,$X:$X,I$17,$U:$U,">=0"),"") -> -0.66666667 | ... N18: =IFERROR((COUNTIFS($Q:$Q,$A18,$X:$X,N$17,$U:$U,">=9") - COUNTIFS($Q:$Q,$A18,$X:$X,N$17,$U:$U,"<=6"))/COUNTIFS($Q:$Q,$A18,$X:$X,N$17,$U:$U,">=0"),"") | Q18: Иванова Анна Сергеевна | R18: Федоров Илья Владимирович | S18: 2023-09-07 | T18: 74884 | U18: 1 | V18: =YEAR(S18) -> 2023 | W18: =MONTH(S18) -> 9 | X18: =V18&"-"&W18 -> 2023-9
A19: Громова Мария Ильинична | B19: =IFERROR((COUNTIFS($Q:$Q,$A19,$X:$X,B$17,$U:$U,">=9") - COUNTIFS($Q:$Q,$A19,$X:$X,B$17,$U:$U,"<=6"))/COUNTIFS($Q:$Q,$A19,$X:$X,B$17,$U:$U,">=0"),"") -> -0.28571429 | C19: =IFERROR((COUNTIFS($Q:$Q,$A19,$X:$X,C$17,$U:$U,">=9") - COUNTIFS($Q:$Q,$A19,$X:$X,C$17,$U:$U,"<=6"))/COUNTIFS($Q:$Q,$A19,$X:$X,C$17,$U:$U,">=0"),"") -> -0.5 | D19: =IFERROR((COUNTIFS($Q:$Q,$A19,$X:$X,D$17,$U:$U,">=9") - COUNTIFS($Q:$Q,$A19,$X:$X,D$17,$U:$U,"<=6"))/COUNTIFS($Q:$Q,$A19,$X:$X,D$17,$U:$U,">=0"),"") -> -0.6 | E19: =IFERROR((COUNTIFS($Q:$Q,$A19,$X:$X,E$17,$U:$U,">=9") - COUNTIFS($Q:$Q,$A19,$X:$X,E$17,$U:$U,"<=6"))/COUNTIFS($Q:$Q,$A19,$X:$X,E$17,$U:$U,">=0"),"") -> -0.33333333 | F19: =IFERROR((COUNTIFS($Q:$Q,$A19,$X:$X,F$17,$U:$U,">=9") - COUNTIFS($Q:$Q,$A19,$X:$X,F$17,$U:$U,"<=6"))/COUNTIFS($Q:$Q,$A19,$X:$X,F$17,$U:$U,">=0"),"") -> -0.35714286 | G19: =IFERROR((COUNTIFS($Q:$Q,$A19,$X:$X,G$17,$U:$U,">=9") - COUNTIFS($Q:$Q,$A19,$X:$X,G$17,$U:$U,"<=6"))/COUNTIFS($Q:$Q,$A19,$X:$X,G$17,$U:$U,">=0"),"") -> 0.4 | H19: =IFERROR((COUNTIFS($Q:$Q,$A19,$X:$X,H$17,$U:$U,">=9") - COUNTIFS($Q:$Q,$A19,$X:$X,H$17,$U:$U,"<=6"))/COUNTIFS($Q:$Q,$A19,$X:$X,H$17,$U:$U,">=0"),"") -> -0.375 | I19: =IFERROR((COUNTIFS($Q:$Q,$A19,$X:$X,I$17,$U:$U,">=9") - COUNTIFS($Q:$Q,$A19,$X:$X,I$17,$U:$U,"<=6"))/COUNTIFS($Q:$Q,$A19,$X:$X,I$17,$U:$U,">=0"),"") -> -0.875 | ... N19: =IFERROR((COUNTIFS($Q:$Q,$A19,$X:$X,N$17,$U:$U,">=9") - COUNTIFS($Q:$Q,$A19,$X:$X,N$17,$U:$U,"<=6"))/COUNTIFS($Q:$Q,$A19,$X:$X,N$17,$U:$U,">=0"),"") | Q19: Громова Мария Ильинична | R19: Федоров Илья Владимирович | S19: 2023-09-07 | T19: 91344 | U19: 4 | V19: =YEAR(S19) -> 2023 | W19: =MONTH(S19) -> 9 | X19: =V19&"-"&W19 -> 2023-9
A20: Иванова Анна Сергеевна | B20: =IFERROR((COUNTIFS($Q:$Q,$A20,$X:$X,B$17,$U:$U,">=9") - COUNTIFS($Q:$Q,$A20,$X:$X,B$17,$U:$U,"<=6"))/COUNTIFS($Q:$Q,$A20,$X:$X,B$17,$U:$U,">=0"),"") -> -0.2 | C20: =IFERROR((COUNTIFS($Q:$Q,$A20,$X:$X,C$17,$U:$U,">=9") - COUNTIFS($Q:$Q,$A20,$X:$X,C$17,$U:$U,"<=6"))/COUNTIFS($Q:$Q,$A20,$X:$X,C$17,$U:$U,">=0"),"") -> 0 | D20: =IFERROR((COUNTIFS($Q:$Q,$A20,$X:$X,D$17,$U:$U,">=9") - COUNTIFS($Q:$Q,$A20,$X:$X,D$17,$U:$U,"<=6"))/COUNTIFS($Q:$Q,$A20,$X:$X,D$17,$U:$U,">=0"),"") -> -0.33333333 | E20: =IFERROR((COUNTIFS($Q:$Q,$A20,$X:$X,E$17,$U:$U,">=9") - COUNTIFS($Q:$Q,$A20,$X:$X,E$17,$U:$U,"<=6"))/COUNTIFS($Q:$Q,$A20,$X:$X,E$17,$U:$U,">=0"),"") -> -0.66666667 | F20: =IFERROR((COUNTIFS($Q:$Q,$A20,$X:$X,F$17,$U:$U,">=9") - COUNTIFS($Q:$Q,$A20,$X:$X,F$17,$U:$U,"<=6"))/COUNTIFS($Q:$Q,$A20,$X:$X,F$17,$U:$U,">=0"),"") -> 0.25 | G20: =IFERROR((COUNTIFS($Q:$Q,$A20,$X:$X,G$17,$U:$U,">=9") - COUNTIFS($Q:$Q,$A20,$X:$X,G$17,$U:$U,"<=6"))/COUNTIFS($Q:$Q,$A20,$X:$X,G$17,$U:$U,">=0"),"") -> -0.33333333 | H20: =IFERROR((COUNTIFS($Q:$Q,$A20,$X:$X,H$17,$U:$U,">=9") - COUNTIFS($Q:$Q,$A20,$X:$X,H$17,$U:$U,"<=6"))/COUNTIFS($Q:$Q,$A20,$X:$X,H$17,$U:$U,">=0"),"") -> 0 | I20: =IFERROR((COUNTIFS($Q:$Q,$A20,$X:$X,I$17,$U:$U,">=9") - COUNTIFS($Q:$Q,$A20,$X:$X,I$17,$U:$U,"<=6"))/COUNTIFS($Q:$Q,$A20,$X:$X,I$17,$U:$U,">=0"),"") -> -0.42857143 | ... N20: =IFERROR((COUNTIFS($Q:$Q,$A20,$X:$X,N$17,$U:$U,">=9") - COUNTIFS($Q:$Q,$A20,$X:$X,N$17,$U:$U,"<=6"))/COUNTIFS($Q:$Q,$A20,$X:$X,N$17,$U:$U,">=0"),"") -> 0 | Q20: Ткаченко Андрей Олегович | R20: Степанова Полина Артемовна | S20: 2023-09-07 | T20: 25225 | U20: 7 | V20: =YEAR(S20) -> 2023 | W20: =MONTH(S20) -> 9 | X20: =V20&"-"&W20 -> 2023-9
A21: Кузнецов Дмитрий Львович | B21: =IFERROR((COUNTIFS($Q:$Q,$A21,$X:$X,B$17,$U:$U,">=9") - COUNTIFS($Q:$Q,$A21,$X:$X,B$17,$U:$U,"<=6"))/COUNTIFS($Q:$Q,$A21,$X:$X,B$17,$U:$U,">=0"),"") -> -0.6 | C21: =IFERROR((COUNTIFS($Q:$Q,$A21,$X:$X,C$17,$U:$U,">=9") - COUNTIFS($Q:$Q,$A21,$X:$X,C$17,$U:$U,"<=6"))/COUNTIFS($Q:$Q,$A21,$X:$X,C$17,$U:$U,">=0"),"") -> -0.71428571 | D21: =IFERROR((COUNTIFS($Q:$Q,$A21,$X:$X,D$17,$U:$U,">=9") - COUNTIFS($Q:$Q,$A21,$X:$X,D$17,$U:$U,"<=6"))/COUNTIFS($Q:$Q,$A21,$X:$X,D$17,$U:$U,">=0"),"") -> -0.83333333 | E21: =IFERROR((COUNTIFS($Q:$Q,$A21,$X:$X,E$17,$U:$U,">=9") - COUNTIFS($Q:$Q,$A21,$X:$X,E$17,$U:$U,"<=6"))/COUNTIFS($Q:$Q,$A21,$X:$X,E$17,$U:$U,">=0"),"") -> -0.33333333 | F21: =IFERROR((COUNTIFS($Q:$Q,$A21,$X:$X,F$17,$U:$U,">=9") - COUNTIFS($Q:$Q,$A21,$X:$X,F$17,$U:$U,"<=6"))/COUNTIFS($Q:$Q,$A21,$X:$X,F$17,$U:$U,">=0"),"") -> -0.6 | G21: =IFERROR((COUNTIFS($Q:$Q,$A21,$X:$X,G$17,$U:$U,">=9") - COUNTIFS($Q:$Q,$A21,$X:$X,G$17,$U:$U,"<=6"))/COUNTIFS($Q:$Q,$A21,$X:$X,G$17,$U:$U,">=0"),"") -> -0.5 | H21: =IFERROR((COUNTIFS($Q:$Q,$A21,$X:$X,H$17,$U:$U,">=9") - COUNTIFS($Q:$Q,$A21,$X:$X,H$17,$U:$U,"<=6"))/COUNTIFS($Q:$Q,$A21,$X:$X,H$17,$U:$U,">=0"),"") -> 0 | I21: =IFERROR((COUNTIFS($Q:$Q,$A21,$X:$X,I$17,$U:$U,">=9") - COUNTIFS($Q:$Q,$A21,$X:$X,I$17,$U:$U,"<=6"))/COUNTIFS($Q:$Q,$A21,$X:$X,I$17,$U:$U,">=0"),"") -> -0.14285714 | ... N21: =IFERROR((COUNTIFS($Q:$Q,$A21,$X:$X,N$17,$U:$U,">=9") - COUNTIFS($Q:$Q,$A21,$X:$X,N$17,$U:$U,"<=6"))/COUNTIFS($Q:$Q,$A21,$X:$X,N$17,$U:$U,">=0"),"") | Q21: Громова Мария Ильинична | R21: Новиков Михаил Владимирович | S21: 2023-09-07 | T21: 46372 | U21: 7 | V21: =YEAR(S21) -> 2023 | W21: =MONTH(S21) -> 9 | X21: =V21&"-"&W21 -> 2023-9
A22: Новикова Ольга Петровна | B22: =IFERROR((COUNTIFS($Q:$Q,$A22,$X:$X,B$17,$U:$U,">=9") - COUNTIFS($Q:$Q,$A22,$X:$X,B$17,$U:$U,"<=6"))/COUNTIFS($Q:$Q,$A22,$X:$X,B$17,$U:$U,">=0"),"") -> -0.44444444 | C22: =IFERROR((COUNTIFS($Q:$Q,$A22,$X:$X,C$17,$U:$U,">=9") - COUNTIFS($Q:$Q,$A22,$X:$X,C$17,$U:$U,"<=6"))/COUNTIFS($Q:$Q,$A22,$X:$X,C$17,$U:$U,">=0"),"") -> -0.30769231 | D22: =IFERROR((COUNTIFS($Q:$Q,$A22,$X:$X,D$17,$U:$U,">=9") - COUNTIFS($Q:$Q,$A22,$X:$X,D$17,$U:$U,"<=6"))/COUNTIFS($Q:$Q,$A22,$X:$X,D$17,$U:$U,">=0"),"") -> -0.5 | E22: =IFERROR((COUNTIFS($Q:$Q,$A22,$X:$X,E$17,$U:$U,">=9") - COUNTIFS($Q:$Q,$A22,$X:$X,E$17,$U:$U,"<=6"))/COUNTIFS($Q:$Q,$A22,$X:$X,E$17,$U:$U,">=0"),"") -> -0.66666667 | F22: =IFERROR((COUNTIFS($Q:$Q,$A22,$X:$X,F$17,$U:$U,">=9") - COUNTIFS($Q:$Q,$A22,$X:$X,F$17,$U:$U,"<=6"))/COUNTIFS($Q:$Q,$A22,$X:$X,F$17,$U:$U,">=0"),"") -> 0 | G22: =IFERROR((COUNTIFS($Q:$Q,$A22,$X:$X,G$17,$U:$U,">=9") - COUNTIFS($Q:$Q,$A22,$X:$X,G$17,$U:$U,"<=6"))/COUNTIFS($Q:$Q,$A22,$X:$X,G$17,$U:$U,">=0"),"") -> -0.33333333 | H22: =IFERROR((COUNTIFS($Q:$Q,$A22,$X:$X,H$17,$U:$U,">=9") - COUNTIFS($Q:$Q,$A22,$X:$X,H$17,$U:$U,"<=6"))/COUNTIFS($Q:$Q,$A22,$X:$X,H$17,$U:$U,">=0"),"") -> 0.33333333 | I22: =IFERROR((COUNTIFS($Q:$Q,$A22,$X:$X,I$17,$U:$U,">=9") - COUNTIFS($Q:$Q,$A22,$X:$X,I$17,$U:$U,"<=6"))/COUNTIFS($Q:$Q,$A22,$X:$X,I$17,$U:$U,">=0"),"") -> -1 | ... N22: =IFERROR((COUNTIFS($Q:$Q,$A22,$X:$X,N$17,$U:$U,">=9") - COUNTIFS($Q:$Q,$A22,$X:$X,N$17,$U:$U,"<=6"))/COUNTIFS($Q:$Q,$A22,$X:$X,N$17,$U:$U,">=0"),"") | Q22: Громова Мария Ильинична | R22: Иванов Александр Павлович | S22: 2023-09-08 | T22: 11951 | U22: 3 | V22: =YEAR(S22) -> 2023 | W22: =MONTH(S22) -> 9 | X22: =V22&"-"&W22 -> 2023-9
A23: Орлов Павел Денисович | B23: =IFERROR((COUNTIFS($Q:$Q,$A23,$X:$X,B$17,$U:$U,">=9") - COUNTIFS($Q:$Q,$A23,$X:$X,B$17,$U:$U,"<=6"))/COUNTIFS($Q:$Q,$A23,$X:$X,B$17,$U:$U,">=0"),"") -> -0.42857143 | C23: =IFERROR((COUNTIFS($Q:$Q,$A23,$X:$X,C$17,$U:$U,">=9") - COUNTIFS($Q:$Q,$A23,$X:$X,C$17,$U:$U,"<=6"))/COUNTIFS($Q:$Q,$A23,$X:$X,C$17,$U:$U,">=0"),"") -> -0.3 | D23: =IFERROR((COUNTIFS($Q:$Q,$A23,$X:$X,D$17,$U:$U,">=9") - COUNTIFS($Q:$Q,$A23,$X:$X,D$17,$U:$U,"<=6"))/COUNTIFS($Q:$Q,$A23,$X:$X,D$17,$U:$U,">=0"),"") -> -0.375 | E23: =IFERROR((COUNTIFS($Q:$Q,$A23,$X:$X,E$17,$U:$U,">=9") - COUNTIFS($Q:$Q,$A23,$X:$X,E$17,$U:$U,"<=6"))/COUNTIFS($Q:$Q,$A23,$X:$X,E$17,$U:$U,">=0"),"") -> -0.77777778 | F23: =IFERROR((COUNTIFS($Q:$Q,$A23,$X:$X,F$17,$U:$U,">=9") - COUNTIFS($Q:$Q,$A23,$X:$X,F$17,$U:$U,"<=6"))/COUNTIFS($Q:$Q,$A23,$X:$X,F$17,$U:$U,">=0"),"") -> -0.28571429 | G23: =IFERROR((COUNTIFS($Q:$Q,$A23,$X:$X,G$17,$U:$U,">=9") - COUNTIFS($Q:$Q,$A23,$X:$X,G$17,$U:$U,"<=6"))/COUNTIFS($Q:$Q,$A23,$X:$X,G$17,$U:$U,">=0"),"") -> 0 | H23: =IFERROR((COUNTIFS($Q:$Q,$A23,$X:$X,H$17,$U:$U,">=9") - COUNTIFS($Q:$Q,$A23,$X:$X,H$17,$U:$U,"<=6"))/COUNTIFS($Q:$Q,$A23,$X:$X,H$17,$U:$U,">=0"),"") -> -1 | I23: =IFERROR((COUNTIFS($Q:$Q,$A23,$X:$X,I$17,$U:$U,">=9") - COUNTIFS($Q:$Q,$A23,$X:$X,I$17,$U:$U,"<=6"))/COUNTIFS($Q:$Q,$A23,$X:$X,I$17,$U:$U,">=0"),"") -> 0.14285714 | ... N23: =IFERROR((COUNTIFS($Q:$Q,$A23,$X:$X,N$17,$U:$U,">=9") - COUNTIFS($Q:$Q,$A23,$X:$X,N$17,$U:$U,"<=6"))/COUNTIFS($Q:$Q,$A23,$X:$X,N$17,$U:$U,">=0"),"") | Q23: Кузнецов Дмитрий Львович | R23: Петров Иван Артемович | S23: 2023-09-08 | T23: 52185 | U23: 4 | V23: =YEAR(S23) -> 2023 | W23: =MONTH(S23) -> 9 | X23: =V23&"-"&W23 -> 2023-9
A24: Петров Владимир Кириллович | B24: =IFERROR((COUNTIFS($Q:$Q,$A24,$X:$X,B$17,$U:$U,">=9") - COUNTIFS($Q:$Q,$A24,$X:$X,B$17,$U:$U,"<=6"))/COUNTIFS($Q:$Q,$A24,$X:$X,B$17,$U:$U,">=0"),"") -> 0 | C24: =IFERROR((COUNTIFS($Q:$Q,$A24,$X:$X,C$17,$U:$U,">=9") - COUNTIFS($Q:$Q,$A24,$X:$X,C$17,$U:$U,"<=6"))/COUNTIFS($Q:$Q,$A24,$X:$X,C$17,$U:$U,">=0"),"") -> -0.6 | D24: =IFERROR((COUNTIFS($Q:$Q,$A24,$X:$X,D$17,$U:$U,">=9") - COUNTIFS($Q:$Q,$A24,$X:$X,D$17,$U:$U,"<=6"))/COUNTIFS($Q:$Q,$A24,$X:$X,D$17,$U:$U,">=0"),"") -> -0.2 | E24: =IFERROR((COUNTIFS($Q:$Q,$A24,$X:$X,E$17,$U:$U,">=9") - COUNTIFS($Q:$Q,$A24,$X:$X,E$17,$U:$U,"<=6"))/COUNTIFS($Q:$Q,$A24,$X:$X,E$17,$U:$U,">=0"),"") -> -0.42857143 | F24: =IFERROR((COUNTIFS($Q:$Q,$A24,$X:$X,F$17,$U:$U,">=9") - COUNTIFS($Q:$Q,$A24,$X:$X,F$17,$U:$U,"<=6"))/COUNTIFS($Q:$Q,$A24,$X:$X,F$17,$U:$U,">=0"),"") -> -0.5 | G24: =IFERROR((COUNTIFS($Q:$Q,$A24,$X:$X,G$17,$U:$U,">=9") - COUNTIFS($Q:$Q,$A24,$X:$X,G$17,$U:$U,"<=6"))/COUNTIFS($Q:$Q,$A24,$X:$X,G$17,$U:$U,">=0"),"") -> -0.4 | H24: =IFERROR((COUNTIFS($Q:$Q,$A24,$X:$X,H$17,$U:$U,">=9") - COUNTIFS($Q:$Q,$A24,$X:$X,H$17,$U:$U,"<=6"))/COUNTIFS($Q:$Q,$A24,$X:$X,H$17,$U:$U,">=0"),"") -> 0 | I24: =IFERROR((COUNTIFS($Q:$Q,$A24,$X:$X,I$17,$U:$U,">=9") - COUNTIFS($Q:$Q,$A24,$X:$X,I$17,$U:$U,"<=6"))/COUNTIFS($Q:$Q,$A24,$X:$X,I$17,$U:$U,">=0"),"") -> -0.33333333 | ... N24: =IFERROR((COUNTIFS($Q:$Q,$A24,$X:$X,N$17,$U:$U,">=9") - COUNTIFS($Q:$Q,$A24,$X:$X,N$17,$U:$U,"<=6"))/COUNTIFS($Q:$Q,$A24,$X:$X,N$17,$U:$U,">=0"),"") | Q24: Фролов Сергей Викторович | R24: Федоров Роман Дмитриевич | S24: 2023-09-08 | T24: 15458 | U24: 7 | V24: =YEAR(S24) -> 2023 | W24: =MONTH(S24) -> 9 | X24: =V24&"-"&W24 -> 2023-9
A25: Семенова Ирина Валерьевна | B25: =IFERROR((COUNTIFS($Q:$Q,$A25,$X:$X,B$17,$U:$U,">=9") - COUNTIFS($Q:$Q,$A25,$X:$X,B$17,$U:$U,"<=6"))/COUNTIFS($Q:$Q,$A25,$X:$X,B$17,$U:$U,">=0"),"") -> -0.5 | C25: =IFERROR((COUNTIFS($Q:$Q,$A25,$X:$X,C$17,$U:$U,">=9") - COUNTIFS($Q:$Q,$A25,$X:$X,C$17,$U:$U,"<=6"))/COUNTIFS($Q:$Q,$A25,$X:$X,C$17,$U:$U,">=0"),"") -> -0.6 | D25: =IFERROR((COUNTIFS($Q:$Q,$A25,$X:$X,D$17,$U:$U,">=9") - COUNTIFS($Q:$Q,$A25,$X:$X,D$17,$U:$U,"<=6"))/COUNTIFS($Q:$Q,$A25,$X:$X,D$17,$U:$U,">=0"),"") -> -0.33333333 | E25: =IFERROR((COUNTIFS($Q:$Q,$A25,$X:$X,E$17,$U:$U,">=9") - COUNTIFS($Q:$Q,$A25,$X:$X,E$17,$U:$U,"<=6"))/COUNTIFS($Q:$Q,$A25,$X:$X,E$17,$U:$U,">=0"),"") -> 0 | F25: =IFERROR((COUNTIFS($Q:$Q,$A25,$X:$X,F$17,$U:$U,">=9") - COUNTIFS($Q:$Q,$A25,$X:$X,F$17,$U:$U,"<=6"))/COUNTIFS($Q:$Q,$A25,$X:$X,F$17,$U:$U,">=0"),"") -> -0.625 | G25: =IFERROR((COUNTIFS($Q:$Q,$A25,$X:$X,G$17,$U:$U,">=9") - COUNTIFS($Q:$Q,$A25,$X:$X,G$17,$U:$U,"<=6"))/COUNTIFS($Q:$Q,$A25,$X:$X,G$17,$U:$U,">=0"),"") -> -0.5 | H25: =IFERROR((COUNTIFS($Q:$Q,$A25,$X:$X,H$17,$U:$U,">=9") - COUNTIFS($Q:$Q,$A25,$X:$X,H$17,$U:$U,"<=6"))/COUNTIFS($Q:$Q,$A25,$X:$X,H$17,$U:$U,">=0"),"") -> 0 | I25: =IFERROR((COUNTIFS($Q:$Q,$A25,$X:$X,I$17,$U:$U,">=9") - COUNTIFS($Q:$Q,$A25,$X:$X,I$17,$U:$U,"<=6"))/COUNTIFS($Q:$Q,$A25,$X:$X,I$17,$U:$U,">=0"),"") -> -0.6 | ... N25: =IFERROR((COUNTIFS($Q:$Q,$A25,$X:$X,N$17,$U:$U,">=9") - COUNTIFS($Q:$Q,$A25,$X:$X,N$17,$U:$U,"<=6"))/COUNTIFS($Q:$Q,$A25,$X:$X,N$17,$U:$U,">=0"),"") -> -1 | Q25: Кузнецов Дмитрий Львович | R25: Новикова Людмила Кирилловна | S25: 2023-09-08 | T25: 37625 | U25: 8 | V25: =YEAR(S25) -> 2023 | W25: =MONTH(S25) -> 9 | X25: =V25&"-"&W25 -> 2023-9
A26: Сидорова Елена Васильевна | B26: =IFERROR((COUNTIFS($Q:$Q,$A26,$X:$X,B$17,$U:$U,">=9") - COUNTIFS($Q:$Q,$A26,$X:$X,B$17,$U:$U,"<=6"))/COUNTIFS($Q:$Q,$A26,$X:$X,B$17,$U:$U,">=0"),"") -> -0.72727273 | C26: =IFERROR((COUNTIFS($Q:$Q,$A26,$X:$X,C$17,$U:$U,">=9") - COUNTIFS($Q:$Q,$A26,$X:$X,C$17,$U:$U,"<=6"))/COUNTIFS($Q:$Q,$A26,$X:$X,C$17,$U:$U,">=0"),"") -> -0.28571429 | D26: =IFERROR((COUNTIFS($Q:$Q,$A26,$X:$X,D$17,$U:$U,">=9") - COUNTIFS($Q:$Q,$A26,$X:$X,D$17,$U:$U,"<=6"))/COUNTIFS($Q:$Q,$A26,$X:$X,D$17,$U:$U,">=0"),"") -> -0.33333333 | E26: =IFERROR((COUNTIFS($Q:$Q,$A26,$X:$X,E$17,$U:$U,">=9") - COUNTIFS($Q:$Q,$A26,$X:$X,E$17,$U:$U,"<=6"))/COUNTIFS($Q:$Q,$A26,$X:$X,E$17,$U:$U,">=0"),"") -> -1 | F26: =IFERROR((COUNTIFS($Q:$Q,$A26,$X:$X,F$17,$U:$U,">=9") - COUNTIFS($Q:$Q,$A26,$X:$X,F$17,$U:$U,"<=6"))/COUNTIFS($Q:$Q,$A26,$X:$X,F$17,$U:$U,">=0"),"") -> -0.090909091 | G26: =IFERROR((COUNTIFS($Q:$Q,$A26,$X:$X,G$17,$U:$U,">=9") - COUNTIFS($Q:$Q,$A26,$X:$X,G$17,$U:$U,"<=6"))/COUNTIFS($Q:$Q,$A26,$X:$X,G$17,$U:$U,">=0"),"") -> 0 | H26: =IFERROR((COUNTIFS($Q:$Q,$A26,$X:$X,H$17,$U:$U,">=9") - COUNTIFS($Q:$Q,$A26,$X:$X,H$17,$U:$U,"<=6"))/COUNTIFS($Q:$Q,$A26,$X:$X,H$17,$U:$U,">=0"),"") -> -0.57142857 | I26: =IFERROR((COUNTIFS($Q:$Q,$A26,$X:$X,I$17,$U:$U,">=9") - COUNTIFS($Q:$Q,$A26,$X:$X,I$17,$U:$U,"<=6"))/COUNTIFS($Q:$Q,$A26,$X:$X,I$17,$U:$U,">=0"),"") -> -0.5 | ... N26: =IFERROR((COUNTIFS($Q:$Q,$A26,$X:$X,N$17,$U:$U,">=9") - COUNTIFS($Q:$Q,$A26,$X:$X,N$17,$U:$U,"<=6"))/COUNTIFS($Q:$Q,$A26,$X:$X,N$17,$U:$U,">=0"),"") | Q26: Фролов Сергей Викторович | R26: Кузнецова Дарья Дмитриевна | S26: 2023-09-11 | T26: 20131 | U26: 10 | V26: =YEAR(S26) -> 2023 | W26: =MONTH(S26) -> 9 | X26: =V26&"-"&W26 -> 2023-9
A27: Ткаченко Андрей Олегович | B27: =IFERROR((COUNTIFS($Q:$Q,$A27,$X:$X,B$17,$U:$U,">=9") - COUNTIFS($Q:$Q,$A27,$X:$X,B$17,$U:$U,"<=6"))/COUNTIFS($Q:$Q,$A27,$X:$X,B$17,$U:$U,">=0"),"") -> -0.75 | C27: =IFERROR((COUNTIFS($Q:$Q,$A27,$X:$X,C$17,$U:$U,">=9") - COUNTIFS($Q:$Q,$A27,$X:$X,C$17,$U:$U,"<=6"))/COUNTIFS($Q:$Q,$A27,$X:$X,C$17,$U:$U,">=0"),"") -> -0.090909091 | D27: =IFERROR((COUNTIFS($Q:$Q,$A27,$X:$X,D$17,$U:$U,">=9") - COUNTIFS($Q:$Q,$A27,$X:$X,D$17,$U:$U,"<=6"))/COUNTIFS($Q:$Q,$A27,$X:$X,D$17,$U:$U,">=0"),"") -> -0.77777778 | E27: =IFERROR((COUNTIFS($Q:$Q,$A27,$X:$X,E$17,$U:$U,">=9") - COUNTIFS($Q:$Q,$A27,$X:$X,E$17,$U:$U,"<=6"))/COUNTIFS($Q:$Q,$A27,$X:$X,E$17,$U:$U,">=0"),"") -> -0.4 | F27: =IFERROR((COUNTIFS($Q:$Q,$A27,$X:$X,F$17,$U:$U,">=9") - COUNTIFS($Q:$Q,$A27,$X:$X,F$17,$U:$U,"<=6"))/COUNTIFS($Q:$Q,$A27,$X:$X,F$17,$U:$U,">=0"),"") -> -0.83333333 | G27: =IFERROR((COUNTIFS($Q:$Q,$A27,$X:$X,G$17,$U:$U,">=9") - COUNTIFS($Q:$Q,$A27,$X:$X,G$17,$U:$U,"<=6"))/COUNTIFS($Q:$Q,$A27,$X:$X,G$17,$U:$U,">=0"),"") -> -1 | H27: =IFERROR((COUNTIFS($Q:$Q,$A27,$X:$X,H$17,$U:$U,">=9") - COUNTIFS($Q:$Q,$A27,$X:$X,H$17,$U:$U,"<=6"))/COUNTIFS($Q:$Q,$A27,$X:$X,H$17,$U:$U,">=0"),"") -> -1 | I27: =IFERROR((COUNTIFS($Q:$Q,$A27,$X:$X,I$17,$U:$U,">=9") - COUNTIFS($Q:$Q,$A27,$X:$X,I$17,$U:$U,"<=6"))/COUNTIFS($Q:$Q,$A27,$X:$X,I$17,$U:$U,">=0"),"") -> -0.71428571 | ... N27: =IFERROR((COUNTIFS($Q:$Q,$A27,$X:$X,N$17,$U:$U,">=9") - COUNTIFS($Q:$Q,$A27,$X:$X,N$17,$U:$U,"<=6"))/COUNTIFS($Q:$Q,$A27,$X:$X,N$17,$U:$U,">=0"),"") -> 0 | Q27: Орлов Павел Денисович | R27: Морозов Сергей Олегович | S27: 2023-09-11 | T27: 15365 | U27: 5 | V27: =YEAR(S27) -> 2023 | W27: =MONTH(S27) -> 9 | X27: =V27&"-"&W27 -> 2023-9
A28: Фролов Сергей Викторович | B28: =IFERROR((COUNTIFS($Q:$Q,$A28,$X:$X,B$17,$U:$U,">=9") - COUNTIFS($Q:$Q,$A28,$X:$X,B$17,$U:$U,"<=6"))/COUNTIFS($Q:$Q,$A28,$X:$X,B$17,$U:$U,">=0"),"") -> 0.375 | C28: =IFERROR((COUNTIFS($Q:$Q,$A28,$X:$X,C$17,$U:$U,">=9") - COUNTIFS($Q:$Q,$A28,$X:$X,C$17,$U:$U,"<=6"))/COUNTIFS($Q:$Q,$A28,$X:$X,C$17,$U:$U,">=0"),"") -> -0.44444444 | D28: =IFERROR((COUNTIFS($Q:$Q,$A28,$X:$X,D$17,$U:$U,">=9") - COUNTIFS($Q:$Q,$A28,$X:$X,D$17,$U:$U,"<=6"))/COUNTIFS($Q:$Q,$A28,$X:$X,D$17,$U:$U,">=0"),"") -> -0.16666667 | E28: =IFERROR((COUNTIFS($Q:$Q,$A28,$X:$X,E$17,$U:$U,">=9") - COUNTIFS($Q:$Q,$A28,$X:$X,E$17,$U:$U,"<=6"))/COUNTIFS($Q:$Q,$A28,$X:$X,E$17,$U:$U,">=0"),"") -> -0.66666667 | F28: =IFERROR((COUNTIFS($Q:$Q,$A28,$X:$X,F$17,$U:$U,">=9") - COUNTIFS($Q:$Q,$A28,$X:$X,F$17,$U:$U,"<=6"))/COUNTIFS($Q:$Q,$A28,$X:$X,F$17,$U:$U,">=0"),"") -> -0.2 | G28: =IFERROR((COUNTIFS($Q:$Q,$A28,$X:$X,G$17,$U:$U,">=9") - COUNTIFS($Q:$Q,$A28,$X:$X,G$17,$U:$U,"<=6"))/COUNTIFS($Q:$Q,$A28,$X:$X,G$17,$U:$U,">=0"),"") -> -0.55555556 | H28: =IFERROR((COUNTIFS($Q:$Q,$A28,$X:$X,H$17,$U:$U,">=9") - COUNTIFS($Q:$Q,$A28,$X:$X,H$17,$U:$U,"<=6"))/COUNTIFS($Q:$Q,$A28,$X:$X,H$17,$U:$U,">=0"),"") -> -0.54545455 | I28: =IFERROR((COUNTIFS($Q:$Q,$A28,$X:$X,I$17,$U:$U,">=9") - COUNTIFS($Q:$Q,$A28,$X:$X,I$17,$U:$U,"<=6"))/COUNTIFS($Q:$Q,$A28,$X:$X,I$17,$U:$U,">=0"),"") -> -0.2 | ... N28: =IFERROR((COUNTIFS($Q:$Q,$A28,$X:$X,N$17,$U:$U,">=9") - COUNTIFS($Q:$Q,$A28,$X:$X,N$17,$U:$U,"<=6"))/COUNTIFS($Q:$Q,$A28,$X:$X,N$17,$U:$U,">=0"),"") | Q28: Новикова Ольга Петровна | R28: Лебедева Анна Викторовна | S28: 2023-09-11 | T28: 65716 | U28: 6 | V28: =YEAR(S28) -> 2023 | W28: =MONTH(S28) -> 9 | X28: =V28&"-"&W28 -> 2023-9
A29: Яковлев Артем Игоревич | B29: =IFERROR((COUNTIFS($Q:$Q,$A29,$X:$X,B$17,$U:$U,">=9") - COUNTIFS($Q:$Q,$A29,$X:$X,B$17,$U:$U,"<=6"))/COUNTIFS($Q:$Q,$A29,$X:$X,B$17,$U:$U,">=0"),"") -> -0.46153846 | C29: =IFERROR((COUNTIFS($Q:$Q,$A29,$X:$X,C$17,$U:$U,">=9") - COUNTIFS($Q:$Q,$A29,$X:$X,C$17,$U:$U,"<=6"))/COUNTIFS($Q:$Q,$A29,$X:$X,C$17,$U:$U,">=0"),"") -> -0.42857143 | D29: =IFERROR((COUNTIFS($Q:$Q,$A29,$X:$X,D$17,$U:$U,">=9") - COUNTIFS($Q:$Q,$A29,$X:$X,D$17,$U:$U,"<=6"))/COUNTIFS($Q:$Q,$A29,$X:$X,D$17,$U:$U,">=0"),"") -> 0 | E29: =IFERROR((COUNTIFS($Q:$Q,$A29,$X:$X,E$17,$U:$U,">=9") - COUNTIFS($Q:$Q,$A29,$X:$X,E$17,$U:$U,"<=6"))/COUNTIFS($Q:$Q,$A29,$X:$X,E$17,$U:$U,">=0"),"") -> -0.5 | F29: =IFERROR((COUNTIFS($Q:$Q,$A29,$X:$X,F$17,$U:$U,">=9") - COUNTIFS($Q:$Q,$A29,$X:$X,F$17,$U:$U,"<=6"))/COUNTIFS($Q:$Q,$A29,$X:$X,F$17,$U:$U,">=0"),"") -> -0.5 | G29: =IFERROR((COUNTIFS($Q:$Q,$A29,$X:$X,G$17,$U:$U,">=9") - COUNTIFS($Q:$Q,$A29,$X:$X,G$17,$U:$U,"<=6"))/COUNTIFS($Q:$Q,$A29,$X:$X,G$17,$U:$U,">=0"),"") -> -1 | H29: =IFERROR((COUNTIFS($Q:$Q,$A29,$X:$X,H$17,$U:$U,">=9") - COUNTIFS($Q:$Q,$A29,$X:$X,H$17,$U:$U,"<=6"))/COUNTIFS($Q:$Q,$A29,$X:$X,H$17,$U:$U,">=0"),"") -> -0.125 | I29: =IFERROR((COUNTIFS($Q:$Q,$A29,$X:$X,I$17,$U:$U,">=9") - COUNTIFS($Q:$Q,$A29,$X:$X,I$17,$U:$U,"<=6"))/COUNTIFS($Q:$Q,$A29,$X:$X,I$17,$U:$U,">=0"),"") -> -0.6 | ... N29: =IFERROR((COUNTIFS($Q:$Q,$A29,$X:$X,N$17,$U:$U,">=9") - COUNTIFS($Q:$Q,$A29,$X:$X,N$17,$U:$U,"<=6"))/COUNTIFS($Q:$Q,$A29,$X:$X,N$17,$U:$U,">=0"),"") | Q29: Яковлев Артем Игоревич | R29: Лебедев Артем Кириллович | S29: 2023-09-11 | T29: 98163 | U29: 8 | V29: =YEAR(S29) -> 2023 | W29: =MONTH(S29) -> 9 | X29: =V29&"-"&W29 -> 2023-9
Q30: Фролов Сергей Викторович | R30: Петрова Валерия Павловна | S30: 2023-09-11 | T30: 11301 | U30: 9 | V30: =YEAR(S30) -> 2023 | W30: =MONTH(S30) -> 9 | X30: =V30&"-"&W30 -> 2023-9
Q31: Петров Владимир Кириллович | R31: Лебедев Илья Станиславович | S31: 2023-09-11 | T31: 16140 | U31: 1 | V31: =YEAR(S31) -> 2023 | W31: =MONTH(S31) -> 9 | X31: =V31&"-"&W31 -> 2023-9
B32: 2023-9 | C32: 2023-10 | D32: 2023-11 | E32: 2023-12 | F32: 2024-1 | G32: 2024-2 | H32: 2024-3 | I32: 2024-4 | J32: 2024-5 | K32: 2024-6 | L32: 2024-7 | M32: 2024-8 | N32: 2024-9 | Q32: Фролов Сергей Викторович | R32: Морозов Максим Андреевич | S32: 2023-09-11 | T32: 97934 | U32: 6 | V32: =YEAR(S32) -> 2023 | W32: =MONTH(S32) -> 9 | X32: =V32&"-"&W32 -> 2023-9
